Workbook

Sheet DASHBOARD
B1: DASHBOARD TÌNH HÌNH TÀI CHÍNH NGÂN HÀNG
B3: AN TOÀN VỐN
B41: HIỆU QUẢ SỬ DỤNG TÀI SẢN
B127: ĐẶC ĐIỂM DANH MỤC HUY ĐỘNG
B185: CHẤT LƯỢNG LỢI NHUẬN
L187: HIỆU QUẢ SỬ DỤNG TÀI SẢN
B218: THANH KHOẢN
B246: RỦI RO THANH KHOẢN
B282: RỦI RO LÃI SUẤT
B301: TÓM TẮT CÁC CHỈ SỐ TÀI CHÍNH CỦA NGÂN HÀNG
B302: AN TOÀN VỐN
B303: Đòn bẩy tài chính của ngân hàng
E304: 2019 | F304: 2020 | G304: 2021 | H304: 2022 | I304: 2023
B305: Vốn chủ sở hữu | E305: =BS!B23 -> 80882982 | F305: =BS!C23 -> 94094979 | G305: =BS!D23 -> 109117393 | H305: =BS!E23 -> 135646085 | I305: =BS!F23 -> 165012666
B306: Đòn bẩy tài chính (A/E) | E306: =BS!B13/BS!B23 -> 15.117134 | F306: =BS!C13/BS!C23 -> 14.094589 | G306: =BS!D13/BS!D23 -> 12.964685 | H306: =BS!E13/BS!E23 -> 13.371674 | I306: =BS!F13/BS!F23 -> 11.148315
B307: An toàn vốn theo chuẩn Basel 2
E308: 2019 | F308: 2020 | G308: 2021 | H308: 2022 | I308: 2023
B309: Vốn cấp 1 | E309: =CAR!B3 -> 80343947 | F309: =CAR!C3 -> 93667389 | G309: =CAR!D3 -> 108687714 | H309: =CAR!E3 -> 134749957 | I309: =CAR!F3 -> 164110931
B310: Vốn cấp 2 | E310: =CAR!B12 -> 14738247 | F310: =CAR!C12 -> 11814657 | G310: =CAR!D12 -> 12478403 | H310: =CAR!E12 -> 14651330 | I310: =CAR!F12 -> 16720193
B311: Hệ số CAR | E311: =CAR!B39 -> 0.093356699 | F311: =CAR!C39 -> 0.09560619 | G311: =CAR!D39 -> 0.093130096 | H311: =CAR!E39 -> 0.099506567 | I311: =CAR!F39 -> 0.11392226
B312: Thay đổi tỷ lệ sở hữu của nhà nước
E313: 2019 | F313: 2020 | G313: 2021 | H313: 2022 | I313: 2023
B314: Tỷ lệ sở hữu của nhà nước | E314: 0.748 | F314: 0.748 | G314: 0.748 | H314: 0.748 | I314: 0.748
B316: HIỆU QUẢ SỬ DỤNG TÀI SẢN
B317: Thanh khoản của ngân hàng
E318: 2019 | F318: 2020 | G318: 2021 | H318: 2022 | I318: 2023
B319: Dự trữ thanh khoản | E319: =BS!B113 -> 297932821 | F319: =BS!C113 -> 316204412 | G319: =BS!D113 -> 266283023 | H319: =BS!E113 -> 424543787 | I319: =BS!F113 -> 409077959
B320: Vay | E320: =BS!B8 -> 724290102 | F320: =BS!C8 -> 820545467 | G320: =BS!D8 -> 934774287 | H320: =BS!E8 -> 1120286832 | I320: =BS!F8 -> 1241675333
B321: Đầu tư | E321: =SUM(BS!B6,BS!B9:B10) -> 171795308 | F321: =SUM(BS!C6,BS!C9:C10) -> 161124164 | G321: =SUM(BS!D6,BS!D9:D10) -> 175716974 | H321: =SUM(BS!E6,BS!E9:E10) -> 199864435 | I321: =SUM(BS!F6,BS!F9:F10) -> 150500420
B322: Tài sản cố định | E322: =BS!B11 -> 6710443 | F322: =BS!C11 -> 8539362 | G322: =BS!D11 -> 8626043 | H322: =BS!E11 -> 7985400 | I322: =BS!F11 -> 7708181
B323: Tài sản có khác | E323: =BS!B12 -> 21891872 | F323: =BS!C12 -> 19816687 | G323: =BS!D12 -> 28969058 | H323: =BS!E12 -> 60978201 | I323: =BS!F12 -> 30651305
B324: Hiệu quả sử dụng tài sản
E325: 2019 | F325: 2020 | G325: 2021 | H325: 2022 | I325: 2023
B326: Tỷ lệ tài sản sinh lãi | E326: =(SUM(BS!B4:B6,BS!B8:B9))/BS!B13 -> 0.963243 | F326: =(SUM(BS!C4:C6,BS!C8:C9))/BS!C13 -> 0.96554863 | G326: =(SUM(BS!D4:D6,BS!D8:D9))/BS!D13 -> 0.95881998 | H326: =(SUM(BS!E4:E6,BS!E8:E9))/BS!E13 -> 0.95056708 | I326: =(SUM(BS!F4:F6,BS!F8:F9))/BS!F13 -> 0.97005388
B327: Tỷ lệ cho vay trên huy đồng (LDR) | E327: 0.7925 | F327: 0.8218 | G327: 0.8618 | H327: 0.9167 | I327: 0.9166
B328: Hiệu quả quản lý hoạt động tín dụng
E329: 2019 | F329: 2020 | G329: 2021 | H329: 2022 | I329: 2023
B330: Tỷ lệ nợ xấu | E330: =SUM(BS!B73:B75)/BS!B76 -> 0.0078996578 | F330: =SUM(BS!C73:C75)/BS!C76 -> 0.0062272471 | G330: =SUM(BS!D73:D75)/BS!D76 -> 0.0063711978 | H330: =SUM(BS!E73:E75)/BS!E76 -> 0.0068296668 | I330: =SUM(BS!F73:F75)/BS!F76 -> 0.009804289
B331: Khả năng bù đắp nợ xấu | E331: =BS!B173/SUM(BS!B73:B75) -> 1.7947811 | F331: =BS!C173/SUM(BS!C73:C75) -> 3.6796138 | G331: =BS!D173/SUM(BS!D73:D75) -> 4.243608 | H331: =BS!E173/SUM(BS!E73:E75) -> 3.1685529 | I331: =BS!F173/SUM(BS!F73:F75) -> 2.3029916
B332: Hiệu quả hoạt động tín dụng
...

Sheet BS
A1: CÂN ĐỐI KẾ TOÁN | B1: 2019 | C1: 2020 | D1: 2021 | E1: 2022 | F1: 2023
A2: TÀI SẢN
A3: Tiền mặt, vàng bạc, đá quý | B3: 13778358 | C3: 15095394 | D3: 18011766 | E3: 18348534 | F3: 14504849
A4: Tiền gửi tại Ngân hàng nhà nước | B4: 34684091 | C4: 33139373 | D4: 22506711 | E4: 92557809 | F4: 58104503
A5: Tiền gửi và cho vay các TCTD khác | B5: 249470372 | C5: 267969645 | D5: 225764546 | E5: 313637444 | F5: 336468607
A6: Chứng khoán kinh doanh ròng | B6: 1801126 | C6: 1954061 | D6: 2766098 | E6: 1499687 | F6: 2495408
A7: Các CCTC phái sinh và TSTC khác | B7: 98312 | D7: 303202 | E7: 156515
A8: Cho vay khách hàng ròng | B8: 724290102 | C8: 820545467 | D8: 934774287 | E8: 1120286832 | F8: 1241675333
A9: Chứng khoán đầu tư | B9: 167529689 | C9: 156931097 | D9: 170604700 | E9: 196171213 | F9: 145780067
A10: Góp vốn, đầu tư dài hạn | B10: 2464493 | C10: 2239006 | D10: 2346176 | E10: 2193535 | F10: 2224945
A11: Tài sản cố định | B11: 6710443 | C11: 8539362 | D11: 8626043 | E11: 7985400 | F11: 7708181
A12: Tài sản Có khác | B12: 21891872 | C12: 19816687 | D12: 28969058 | E12: 60978201 | F12: 30651305
A13: TỔNG CỘNG TÀI SẢN | B13: 1222718858 | C13: 1326230092 | D13: 1414672587 | E13: 1813815170 | F13: 1839613198
A14: NGUỒN VỐN
A15: Nợ phải trả | B15: =SUM(B16:B22) -> 1141835876 | C15: =SUM(C16:C22) -> 1232135113 | D15: =SUM(D16:D22) -> 1305555194 | E15: =SUM(E16:E22) -> 1678169085 | F15: =SUM(F16:F22) -> 1674600532
A16: Các khoản nợ Chính phủ và NHNN | B16: 92365806 | C16: 41176995 | D16: 9468116 | E16: 67314816 | F16: 1670837
A17: Tiền gửi và vay các TCTD khác | B17: 73617085 | C17: 103583833 | D17: 109757777 | E17: 232510850 | F17: 213838980
A18: Tiền gửi của khách hàng | B18: 928450869 | C18: 1032113567 | D18: 1135323913 | E18: 1243468471 | F18: 1395697611
A19: Các CCTC phái sinh và nợ tài chính khác | C19: 52031 | F19: 117752
A20: Vốn tài trợ, uỷ thác của CP và TCTD khác | B20: 20431 | C20: 14679 | D20: 7707 | E20: 3298 | F20: 365
A21: Phát hành giấy tờ có giá | B21: 21383932 | C21: 21240197 | D21: 17387747 | E21: 25337894 | F21: 19912623
A22: Các khoản nợ khác | B22: 25997753 | C22: 33953811 | D22: 33609934 | E22: 109533756 | F22: 43362364
A23: Vốn chủ sở hữu | B23: 80882982 | C23: 94094979 | D23: 109117393 | E23: 135646085 | F23: 165012666
A24: Vốn của tổ chức tín dụng | B24: 42428820 | C24: 42428821 | D24: 42428821 | E24: 53130392 | F24: 61696139
A25: Quỹ của tổ chức tín dụng | B25: 12186141 | C25: 14925803 | D25: 18173068 | E25: 22556958 | F25: 27447116
A26: Chênh lệch đánh giá lại tài sản | B26: 113011
A27: Chênh lệch tỷ giá hối đoái | B27: 16361 | C27: 5103 | D27: -5109 | E27: -863071 | F27: -983237
A28: Lợi nhuận chưa phân phối lũy kế | B28: 26055190 | C28: 36650228 | D28: 48433500 | E28: 60733423 | F28: 76758658
A29: Lợi ích của cổ đông thiểu số | B29: 83459 | C29: 85024 | D29: 87113 | E29: 88383 | F29: 93990
A30: TỔNG CỘNG NGUỒN VỐN | B30: 1222718858 | C30: 1326230092 | D30: 1414672587 | E30: 1813815170 | F30: 1839613198
A31: SLCP (cổ phiếu) | B31: 3700658435 | C31: 3708877448 | D31: 4732516571 | E31: 4732516571 | F31: 5589091262
A34: PHÂN TÍCH DANH MỤC TÍN DỤNG
A35: PHÂN THEO PHƯƠNG THỨC CẤP TD | B35: 2019 | C35: 2020 | D35: 2021 | E35: 2022 | F35: 2023
A36: 1. Cho vay các tổ chức kinh tế, cá nhân trong nước | B36: 726968213 | C36: 832010220 | D36: 951443830 | E36: 1136450786 | F36: 1258418586
A37: 2. Cho vay chiết khấu công cụ chuyển nhượng và các giấy tờ có giá | B37: 3172630 | C37: 2549713 | D37: 3879226 | E37: 2908120 | F37: 3396873
A38: 3. Cho thuê tài chính | B38: 4429029 | C38: 4608056 | D38: 4376120 | E38: 4991115 | F38: 6055394
A39: 4. Các khoản trả thay khách hàng | B39: 1000 | D39: 889 | E39: 7409 | F39: 1646618
A40: 5. Cho vay đối với các tổ chức, cá nhân nước ngoài | B40: 136019 | C40: 620272 | D40: 1049890 | E40: 708820 | F40: 841547
A41: TỔNG | B41: =SUM(B36:B40) -> 734706891 | C41: =SUM(C36:C40) -> 839788261 | D41: =SUM(D36:D40) -> 960749955 | E41: =SUM(E36:E40) -> 1145066250 | F41: =SUM(F36:F40) -> 1270359018
A42: PHÂN THEO THỜI HẠN
...

Sheet CAR
B1: 2019 | C1: 2020 | D1: 2021 | E1: 2022 | F1: 2023
A2: VỐN TỰ CÓ
A3: VỐN CẤP 1 | B3: 80343947 | C3: 93667389 | D3: 108687714 | E3: 134749957 | F3: 164110931
A4: Vốn của tổ chức tín dụng
A5: Vốn dự trữ bổ sung vốn điều lệ
A6: Các quỹ của ngân hàng
A7: Lợi nhuận chưa phân phối
A8: Chênh lệch tỷ giá hoái đoái
A9: Lợi thế thương mại
A10: Cổ phiếu quỹ
A11: Góp vốn vào các doanh nghiệp và tổ chức tín dụng khác
A12: VỐN CẤP 2 | B12: 14738247 | C12: 11814657 | D12: 12478403 | E12: 14651330 | F12: 16720193
A13: 50% Chênh lệch đánh giá lại tài sản
A14: Dự phòng chung
A15: Trái phiếu kỳ hạn trên 5 năm
A16: Phần giá trị chênh lệch dương giữa dự phòng chung và 1,25% của "Tổng tài sản có rủi ro" quy định tại Phụ lục
A17: Phần giá trị chênh lệch dương giữa khoản mục trái phiếu và 50% của vốn cấp 1
A18: Các khoản giảm trừ (đồng) (Y) | B18: -1612388 | C18: -1342388 | D18: -1194876 | E18: -1193012 | F18: -1190076
A19: VỐN TỰ CÓ | B19: =B3+B12+B18 -> 93469806 | C19: =C3+C12+C18 -> 104139658 | D19: =D3+D12+D18 -> 119971241 | E19: =E3+E12+E18 -> 148208275 | F19: =F3+F12+F18 -> 179641048
A21: TÀI SẢN CÓ RỦI RO
B22: 2019 | C22: 2020 | D22: 2021 | E22: 2022 | F22: 2023
A23: Tiền mặt, vàng bạc, đá quý (Y) | B23: 0 | C23: 0 | D23: 0 | E23: 0 | F23: 0
A24: Khoản phải đòi Chính phủ (trong và ngoài nước) (Y) | B24: 439293 | C24: 217272 | D24: 318966 | E24: 224416 | F24: 399239
A25: Khoản phải đòi Tổ chức tài chính (Y) | B25: 162610224 | C25: 188305681 | D25: 197646089 | E25: 180889879 | F25: 233493158
A26: Cho vay Thế chấp nhà ở (Y) | B26: 0 | C26: 0 | D26: 0 | E26: 0 | F26: 0
A27: Cho vay Đảm bảo bằng BĐS (Y) | B27: 0 | C27: 0 | D27: 0 | E27: 0 | F27: 0
A28: Danh mục cấp tín dụng bán lẻ (Y) | B28: 239476405 | C28: 296751828 | D28: 360955989 | E28: 441741395 | F28: 443923361
A29: Khoản phải đòi Doanh nghiệp (Y) | B29: 467673104 | C29: 456968779 | D29: 553865877 | E29: 658098446 | F29: 704560933
A30: Các khoản phải đòi khác (Y) | B30: 10115049 | C30: 9463306 | D30: 7338279 | E30: 4021738 | F30: 0
A31: Nợ xấu (Y) | B31: 1639280 | C31: 1365829 | D31: 10442119 | E31: 1906348 | F31: 4203669
A32: Cho thuê tài chính (Y) | B32: 6633031 | C32: 6850823 | D32: 6380496 | E32: 7344027 | F32: 8591933
A33: Các loại tài sản khác (Y) | B33: 16277824 | C33: 21509298 | D33: 31097247 | E33: 61216035 | F33: 30111973
A34: Tổng tài sản có rủi ro tín dụng (Y) | B34: 904864210 | C34: 976688767 | D34: 1168045062 | E34: 1355442284 | F34: 1425284266
... A37: Vốn yêu cầu cho rủi ro hoạt động (đồng) (Y) | B37: 6841243 | C37: 7979568 | D37: 8984080 | E37: 10255744 | F37: 11584278
A38: Tỷ lệ an toàn vốn cấp 1 (Y) | B38: =B3/(SUM(B34:B35)+12.5*SUM(B36:B37)) -> 0.080246724 | C38: =C3/(SUM(C34:C35)+12.5*SUM(C36:C37)) -> 0.085992045 | D38: =D3/(SUM(D34:D35)+12.5*SUM(D36:D37)) -> 0.08437103 | E38: =E3/(SUM(E34:E35)+12.5*SUM(E36:E37)) -> 0.090470695 | F38: =F3/(SUM(F34:F35)+12.5*SUM(F36:F37)) -> 0.10407359
A39: Tỷ lệ an toàn vốn (Y) | B39: =B19/(SUM(B34:B35)+12.5*SUM(B36:B37)) -> 0.093356699 | C39: =C19/(SUM(C34:C35)+12.5*SUM(C36:C37)) -> 0.09560619 | D39: =D19/(SUM(D34:D35)+12.5*SUM(D36:D37)) -> 0.093130096 | E39: =E19/(SUM(E34:E35)+12.5*SUM(E36:E37)) -> 0.099506567 | F39: =F19/(SUM(F34:F35)+12.5*SUM(F36:F37)) -> 0.11392226

Sheet IS
A1: BÁO CÁO KQKD | B1: 2019 | C1: 2020 | D1: 2021 | E1: 2022 | F1: 2023
A2: Thu nhập lãi thuần | B2: 34577350 | C2: 36285475 | D2: 42399617 | E2: 53246478 | F2: 53620869
A3: -TN từ lãi và các khoản TN tương tự | B3: 67724190 | C3: 69205134 | D3: 70749002 | E3: 88112700 | F3: 108122278
A4: -CP lãi và các CP tương tự | B4: -33146840 | C4: -32919659 | D4: -28349385 | E4: -34866222 | F4: -54501409
A5: Lãi/Lỗ thuần từ HĐ DV | B5: 4306844 | C5: 6607317 | D5: 7407073 | E5: 6839100 | F5: 5779723
A6: -TN từ hoạt động dịch vụ | B6: 9002507 | C6: 10588163 | D6: 11286516 | E6: 12425007 | F6: 12632739
A7: -CPhoạt động dịch vụ | B7: -4695663 | C7: -3980846 | D7: -3879443 | E7: -5585907 | F7: -6853016
A8: Lãi/Lỗ thuần từ HĐKDNH | B8: 3378274 | C8: 3906399 | D8: 4374820 | E8: 5768445 | F8: 5660028
A9: Lãi/Lỗ thuần từ MB CKKD | B9: 145982 | C9: 1810 | D9: 104114 | E9: -115194 | F9: 124217
A10: Lãi/Lỗ thuần từ MB CKĐT | B10: 7040 | C10: -98 | D10: -85126 | E10: 81595
A11: Lãi/Lỗ thuần từ HĐ khác | B11: 3069795 | C11: 1800253 | D11: 2393261 | E11: 2053961 | F11: 2272169
A12: Thu nhập từ hoạt động khác | B12: 3427765 | C12: 2544714 | D12: 3100370 | E12: 2928339 | F12: 4050144
A13: Chi phí hoạt động khác | B13: -357970 | C13: -744461 | D13: -707109 | E13: -874378 | F13: -1777975
A14: TN từ HĐ góp vốn mua CP | B14: 245096 | C14: 461385 | D14: 129810 | E14: 208436 | F14: 266456
A15: Tổng thu nhập hoạt động | B15: =SUM(B2,B5,B8:B11,B14) -> 45730381 | C15: =SUM(C2,C5,C8:C11,C14) -> 49062541 | D15: =SUM(D2,D5,D8:D11,D14) -> 56723569 | E15: =SUM(E2,E5,E8:E11,E14) -> 68082821 | F15: =SUM(F2,F5,F8:F11,F14) -> 67723462
A16: Chi phí hoạt động | B16: -15817575 | C16: -16038250 | D16: -17574188 | E16: -21250512 | F16: -21914899
A17: Lợi nhuận từ HDKD trước CPDP RRTD | B17: 29912806 | C17: 33024291 | D17: 39149381 | E17: 46832309 | F17: 45808563
A18: Chi phí dự phòng RRTD | B18: -6790429 | C18: -9974730 | D18: -11760801 | E18: -9464218 | F18: -4564876
A19: Tổng lợi nhuận trước thuế | B19: =B17+B18 -> 23122377 | C19: =C17+C18 -> 23049561 | D19: =D17+D18 -> 27388580 | E19: =E17+E18 -> 37368091 | F19: =F17+F18 -> 41243687
A20: Chi phí thuế TNDN | B20: -4596389 | C20: -4577043 | D20: -5449535 | E20: -7449037 | F20: -8189239
A21: Chi phí thuế TN hiện hành | B21: -4992464 | C21: -5081068 | D21: -4547363 | E21: -8406860 | F21: -8079401
A22: Chi phí thuế TNDN giữ lại | B22: 396075 | C22: 504025 | D22: -902172 | E22: 957823 | F22: -109838
A23: LNST TNDN | B23: =B19+B20 -> 18525988 | C23: =C19+C20 -> 18472518 | D23: =D19+D20 -> 21939045 | E23: =E19+E20 -> 29919054 | F23: =F19+F20 -> 33054448
A24: Lợi ích của cổ đông thiểu số | B24: 15090 | C24: 21207 | D24: 20232 | E24: 20040 | F24: 21245
A25: Lợi nhuận sau thuế Ngân hàng mẹ | B25: 18510898 | C25: 18451311 | D25: 21918813 | E25: 29899014 | F25: 33033203
A28: THU NHẬP BÌNH QUÂN THEO THỜI GIAN
B30: 2019 | C30: 2020 | D30: 2021 | E30: 2022 | F30: 2023
A31: Tổng số cán bộ, công nhân viên | B31: 18948 | C31: 20062 | D31: 21670 | E31: 22599 | F31: 23493
A32: Tổng quỹ lương và phụ cấp | B32: 7807100 | C32: 7674765 | D32: 8499318 | E32: 9564154 | F32: 10553274
A33: Thu nhập bình quân tháng/người (triệu VND) | B33: =B32/B31/12 -> 34.335638 | C33: =C32/C31/12 -> 31.879361 | D33: =D32/D31/12 -> 32.684656 | E33: =E32/E31/12 -> 35.267615 | F33: =F32/F31/12 -> 37.434108

Sheet CF
A1: BÁO CÁO LCTT: PPTT | B1: 2015 | C1: 2016 | D1: 2017 | E1: 2018 | F1: 2019
A2: LCTT từ HĐKD
A3: 1. Thu nhập lãi và các khoản tương tự | B3: 66956606 | C3: 70063617 | D3: 70805813 | E3: 86084771 | F3: 108115649
A4: 2. Chi phí lãi và các khoản tương tự | B4: -31567168 | C4: -33194191 | D4: -28835100 | E4: -31709129 | F4: -47454819
A5: 3. Thu nhập từ HĐ dịch vụ nhận được | B5: 4306844 | C5: 6607317 | D5: 5727973 | E5: 5160000 | F5: 4100623
A6: 4. Thu nhập từ HĐ kinh doanh ngoại tệ, vàng | B6: 3068655 | C6: 3464399 | D6: 4666765 | E6: 6001404 | F6: 5242957
A7: 5. Thu nhập từ HĐ kinh doanh chứng khoán
A8: 6. Thu nhập khác | B8: -115005 | C8: -628988 | D8: -526224 | E8: -351728 | F8: 179388
A9: 7. Tiền thu từ các khoản nợ đã được xử lý | B9: 3179526 | C9: 2421725 | D9: 2912230 | E9: 2394744 | F9: 2090116
A10: 8. Tiền trả cho nhân viên và nhà cung cấp | B10: -14532712 | C10: -14525026 | D10: -16384599 | E10: -19834116 | F10: -19932948
A11: 9. Tiền chi nộp thuế TNDN | B11: -4827328 | C11: -4680317 | D11: -5877802 | E11: -3976351 | F11: -8969967
A12: Tăng/giảm về tài sản hoạt động
A13: 10. (Tăng)/Giảm về tiền gửi và cho vay TCTD khác | B13: 2189341 | C13: 4040576 | D13: -13107318 | E13: -15019465 | F13: 10780289
A14: 11. (Tăng)/giảm về kinh doanh chứng khoán | B14: -17562680 | C14: 10336784 | D14: -14079392 | E14: 5431755 | F14: 19792999
A15: 12. (Tăng)/Giảm CCTC phái sinh và TSTC khác | B15: 177671 | C15: 98312 | D15: -303202 | E15: 146687 | F15: 156515
A16: 13. (Tăng)/Giảm các khoản cho vay khách hàng | B16: -102840133 | C16: -105081370 | D16: -120961694 | E16: -184316295 | F16: -125292768
A17: 14. (Tăng)/Giảm lãi, phí phải thu
A18: 15. Tăng/(Giảm) nguồn dự phòng bù đắp tổn thất | B18: -4502397 | C18: -2805965 | D18: -2538370 | E18: -3530346 | F18: -5758202
A19: 16. (Tăng)/Giảm khác về tài sản hoạt động | B19: -3354149 | C19: 1613500 | D19: -9978820 | E19: -28925742 | F19: 30781829
A20: Tăng giảm về nợ hoạt động
A21: 17. Tăng/(Giảm) khoản nợ chính phủ và NHNN | B21: 1680491 | C21: -51188811 | D21: -31708879 | E21: 57846700 | F21: -65643979
A22: 18. Tăng/(Giảm) khoản tiền gửi và vay TCTD khác | B22: -2906994 | C22: 29966748 | D22: 6173944 | E22: 122753073 | F22: -18671870
A23: 19. Tăng/(Giảm) tiền gửi của khách hàng | B23: 126521754 | C23: 103662698 | D23: 103210346 | E23: 108144558 | F23: 152229140
A24: 20. Tăng/(Giảm) CCTC phái sinh và nợ TC khác | C24: 52031 | D24: -52031 | F24: 117752
A25: 21. Tăng/(Giảm) phát hành giấy tờ có giá | B25: -77572 | C25: -144015 | D25: -3853426 | E25: 7950797 | F25: -5425274
A26: 22. Tăng/(Giảm) vốn uỷ thác của CP và TCTD khác | B26: -5372 | C26: -5752 | D26: -6972 | E26: -4409 | F26: -2933
A27: 23. Tăng/(Giảm) lãi, phí phải trả
A28: 24. Tăng/(Giảm) khác về công nợ hoạt động | B28: 720675 | C28: 7396305 | D28: 950748 | E28: 71713235 | F28: -72173193
A29: 25. Tăng/(Giảm) chi từ các quỹ của TCTD | B29: -1434221 | C29: -1866142 | D29: -2786463 | E29: -2538654 | F29: -2802834
A30: LCTT thuần từ HĐKD | B30: 25075832 | C30: 25603435 | D30: -56552473 | E30: 183421489 | F30: -38541530
A31: Lưu chuyển tiền từ hoạt động đầu tư
A32: 1. Tiền mua TSCĐ và các TSDH khác | B32: -1005065 | C32: -3001902 | D32: -1621433 | E32: -711567 | F32: -1008160
A33: 2. Tiền thu được từ thanh lý, nhượng bán TSCĐ | B33: 11589 | C33: 10569 | D33: 8456 | E33: 15753 | F33: 9435
A34: 3. Tiền chi từ thanh lý, nhượng bán TSCĐ | B34: -6315 | C34: -3053 | D34: -1201 | E34: -4808 | F34: -6770
A35: 4. Mua sắm Bất động sản đầu tư
A36: 5. Tiền thu từ bán, thanh lý BĐS đầu tư
A37: 6. Tiền chi cho việc bán, thanh lý BĐS đầu tư
A38: 7. Tiền chi đầu tư, góp vốn vào đơn vị khác | D38: -83502
A39: 8. Tiền thu hồi đầu tư, góp vốn vào đơn vị khác | B39: 95773 | C39: 605274 | D39: 13791 | E39: 201899
A40: 9. Tiền thu từ cổ tức và lợi nhuận được chia | B40: 197571 | C40: 83959 | D40: 93953 | E40: 106555 | F40: 146088
...

Sheet KEY RATIOS
A1: 1 | B1: TÓM TẮT THÔNG TIN TÀI CHÍNH
F2: Đvt: triệu đồng
B3: KẾT QUẢ KINH DOANH | C3: 2020 | D3: 2021 | E3: 2022 | F3: 2023
B4: Tổng thu nhập | C4: 49062541 | D4: 56723569 | E4: 68082821 | F4: 67723462
B5: Tổng chi phí | C5: -16038250 | D5: -17574188 | E5: -21250512 | F5: -21914899
B6: Lợi nhuận trước thuế | C6: 23049561 | D6: 27388580 | E6: 37368091 | F6: 41243687
B7: Lợi nhuận sau thuế | C7: 18472518 | D7: 21939045 | E7: 29919054 | F7: 33054448
B8: LNST của CĐ cty mẹ | C8: 18451311 | D8: 21918813 | E8: 29899014 | F8: 33033203
B9: CÂN ĐỐI KẾ TOÁN | C9: 2020 | D9: 2021 | E9: 2022 | F9: 2023
B10: Tổng tài sản Có | C10: 1813815170 | D10: 1414672587 | E10: 1326230092 | F10: 1222718858
B11: - Cho vay khách hàng ròng | C11: 1120286832 | D11: 934774287 | E11: 820545467 | F11: 724290102
B12: - Các khoản đầu tư (CKKD), CKĐT, Góp vốn dài hạn | C12: 161124164 | D12: 175716974 | E12: 199864435 | F12: 150500420
B13: Tổng nợ phải trả | C13: 1232135113 | D13: 1305555194 | E13: 1678169085 | F13: 1674600532
B14: - Tiền gửi (Khách hàng+TCTD) | C14: 1135697400 | D14: 1245081690 | E14: 1475979321 | F14: 1609536591
... B16: CHỈ TIÊU CƠ BẢN | C16: 2020 | D16: 2021 | E16: 2022 | F16: 2023
B17: ROA | C17: =C7/AVERAGE(BS!B$13:C$13) -> 0.014494224 | D17: =D7/AVERAGE(BS!C$13:D$13) -> 0.016008627 | E17: =E7/AVERAGE(BS!D$13:E$13) -> 0.018534408 | F17: =F7/AVERAGE(BS!E$13:F$13) -> 0.01809503
B18: ROE | C18: =C7/AVERAGE(BS!B23:C23) -> 0.21114108 | D18: =D7/AVERAGE(BS!C23:D23) -> 0.21592234 | E18: =E7/AVERAGE(BS!D23:E23) -> 0.24447319 | F18: =F7/AVERAGE(BS!E23:F23) -> 0.21988017
B19: Lãi cơ bản trên cổ phiếu - EPS (VND) | C19: 4470 | D19: 4195 | E19: 5821 | F19: 5449
B20: BVPS | C20: 19203.68 | D20: 22389.116 | E20: 28049.006 | F20: 29043.381
B21: P/E | C21: 25.110052 | D21: 14.405593 | E21: 10.722115 | F21: 13.586452
A24: 2 | B24: CÁC CHỈ SỐ TÀI CHÍNH
B27: Các tỷ số VCB | C27: 2020 | D27: 2021 | E27: 2022 | F27: 2023
B28: Tỷ suất sinh lời | H28: Công thức
B29: ROE | C29: =C7/AVERAGE(BS!B23:C23) -> 0.21114108 | D29: =D7/AVERAGE(BS!C23:D23) -> 0.21592234 | E29: =E7/AVERAGE(BS!D23:E23) -> 0.24447319 | F29: =F7/AVERAGE(BS!E23:F23) -> 0.21988017 | H29: Lợi nhuận sau thuế / Trung bình vốn chủ sở hữu đầu kỳ và cuối kỳ
B30: ROA | C30: =C7/AVERAGE(BS!B$13:C$13) -> 0.014494224 | D30: =D7/AVERAGE(BS!C$13:D$13) -> 0.016008627 | E30: =E7/AVERAGE(BS!D$13:E$13) -> 0.018534408 | F30: =F7/AVERAGE(BS!E$13:F$13) -> 0.01809503 | H30: Lợi nhuận sau thuế / Trung bình tổng tài sản đầu kỳ và cuối kỳ
B31: NIM (CV) | C31: =IS!C2/(SUM(BS!B8:C8)/2) -> 0.046976488 | D31: =IS!D2/(SUM(BS!C8:D8)/2) -> 0.04830985 | E31: =IS!E2/(SUM(BS!D8:E8)/2) -> 0.051819849 | F31: =IS!F2/(SUM(BS!E8:F8)/2) -> 0.045403665 | H31: Thu nhập lãi thuần/ Trung bình Cho vay khách hàng đầu kỳ và cuối kỳ
B32: NIM (TSSL) | C32: =IS!C2/AVERAGE(SUM(BS!B4:B6,BS!B8:B9),SUM(BS!C4:C6,BS!C8:C9)) -> 0.029520606 | D32: =IS!D2/AVERAGE(SUM(BS!C4:C6,BS!C8:C9),SUM(BS!D4:D6,BS!D8:D9)) -> 0.032158001 | E32: =IS!E2/AVERAGE(SUM(BS!D4:D6,BS!D8:D9),SUM(BS!E4:E6,BS!E8:E9)) -> 0.034569245 | F32: =IS!F2/AVERAGE(SUM(BS!E4:E6,BS!E8:E9),SUM(BS!F4:F6,BS!F8:F9)) -> 0.030564723 | H32: Thu nhập lãi thuần/ Trung bình (Tiền gửi tại NHNN + Tiền gửi và cho vay các TCTD khác + Chứng khoán kinh doanh + Cho vay khách hàng + Chứng khoán đầu tư)
B33: YEA | C33: =IS!C3/AVERAGE(SUM(BS!B4:B6,BS!B8:B9),SUM(BS!C4:C6,BS!C8:C9)) -> 0.056302901 | D33: =IS!D3/AVERAGE(SUM(BS!C4:C6,BS!C8:C9),SUM(BS!D4:D6,BS!D8:D9)) -> 0.0536596 | E33: =IS!E3/AVERAGE(SUM(BS!D4:D6,BS!D8:D9),SUM(BS!E4:E6,BS!E8:E9)) -> 0.057205465 | F33: =IS!F3/AVERAGE(SUM(BS!E4:E6,BS!E8:E9),SUM(BS!F4:F6,BS!F8:F9)) -> 0.061631368 | H33: Thu nhập lãi và các khoản tương tự/ Trung bình (Tiền gửi tại NHNN + Tiền gửi và cho vay các TCTD khác + Chứng khoán kinh doanh + Cho vay khách hàng + Chứng khoán đầu tư)
B34: COF | C34: =ABS(IS!C4)/AVERAGE(SUM(BS!B16:B18,BS!B21),SUM(BS!C16:C18,BS!C21)) -> 0.028453433 | D34: =ABS(IS!D4)/AVERAGE(SUM(BS!C16:C18,BS!C21),SUM(BS!D16:D18,BS!D21)) -> 0.022954483 | E34: =ABS(IS!E4)/AVERAGE(SUM(BS!D16:D18,BS!D21),SUM(BS!E16:E18,BS!E21)) -> 0.024548754 | F34: =ABS(IS!F4)/AVERAGE(SUM(BS!E16:E18,BS!E21),SUM(BS!F16:F18,BS!F21)) -> 0.03406602 | H34: Chi phí lãi và các khoản tương tự/ Trung bình (Các khoản nợ chính phủ và NHNN + Tiền gửi và vay các TCTD khác + Tiền gửi của khách hàng + Phát hành giấy tờ có giá) đầu kỳ và cuối kỳ
B35: Hiệu quả hoạt động | H35: Hiệu quả hoạt động
B36: Chênh lệch lợi suất (YEA - COF) | C36: =C33-C34 -> 0.027849468 | D36: =D33-D34 -> 0.030705117 | E36: =E33-E34 -> 0.032656711 | F36: =F33-F34 -> 0.027565348 | H36: YEA - COF
B37: Tỷ lệ CIR | C37: =ABS(IS!C16)/IS!C15 -> 0.32689399 | D37: =ABS(IS!D16)/IS!D15 -> 0.30982162 | E37: =ABS(IS!E16)/IS!E15 -> 0.31212737 | F37: =ABS(IS!F16)/IS!F15 -> 0.3235939 | H37: Tổng chi phí hoạt động / Tổng thu nhập hoạt động
B38: Chất lượng danh mục tài sản | H38: Chất lượng danh mục tài sản
B39: Tỷ lệ nợ xấu | C39: =SUM(BS!C73:C75)/BS!C76 -> 0.0062272471 | D39: =SUM(BS!D73:D75)/BS!D76 -> 0.0063711978 | E39: =SUM(BS!E73:E75)/BS!E76 -> 0.0068296668 | F39: =SUM(BS!F73:F75)/BS!F76 -> 0.009804289 | H39: (Nợ dưới tiêu chuẩn + Nợ nghi ngờ + Nợ xấu có khả năng mất vốn) / Cho vay khách hàng
B40: Hệ số bao phủ nợ xấu (LLR) | C40: =BS!C173/SUM(BS!C73:C75) -> 3.6796138 | D40: =BS!D173/SUM(BS!D73:D75) -> 4.243608 | E40: =BS!E173/SUM(BS!E73:E75) -> 3.1685529 | F40: =BS!F173/SUM(BS!F73:F75) -> 2.3029916 | H40: Dự phòng rủi ro cho vay khách hàng / (Nợ dưới tiêu chuẩn + Nợ nghi ngờ + Nợ xấu có khả năng mất vốn)
B41: Thanh khoản | H41: Thanh khoản
B42: Tỷ lệ dự trữ | C42: =BS!C4/BS!C18 -> 0.032108262 | D42: =BS!D4/BS!D18 -> 0.019824044 | E42: =BS!E4/BS!E18 -> 0.074435188 | F42: =BS!F4/BS!F18 -> 0.041631155 | H42: Tiền gửi tại ngân hàng nhà nước / Tiền gửi của khách hàng
B43: Tỷ lệ cho vay/Huy động (LDR)* | C43: =BS!C8/SUM(BS!C17:C18,BS!C21) -> 0.70923918 | D43: =BS!D8/SUM(BS!D17:D18,BS!D21) -> 0.7404332 | E43: =BS!E8/SUM(BS!E17:E18,BS!E21) -> 0.74620262 | F43: =BS!F8/SUM(BS!F17:F18,BS!F21) -> 0.7620215 | H43: 1. Tính đơn giản: Cho vay khách hàng/ (Tiền gửi của khách hàng + Tiền gửi của các TCTD khác + Phát hành giấy tờ có giá) 2. LDR tính đúng theo Thông tư 26/2022/TT-NHNN sửa đổi Thông tư 22/2019/TT-NHNN: (Cho vay khách hàng - Cho vay bằng vốn tài trợ, uỷ thác đầu tư - Cho vay theo chỉ định của Chính phủ) / (Tiền gửi của khách hàng + Tiền gửi của các TCTD khác - Tiền gửi vốn chuyên dụng - Tiền gửi ký quỹ + Phát hành giấy tờ có giá + Tiền gửi có kỳ hạn của KBNN *40%)
B44: Tỷ lệ CASA | C44: =SUM(BS!C83,BS!C86)/BS!C87 -> 0.30150074 | D44: =SUM(BS!D83,BS!D86)/BS!D87 -> 0.32894439 | E44: =SUM(BS!E83,BS!E86)/BS!E87 -> 0.33129286 | F44: =SUM(BS!F83,BS!F86)/BS!F87 -> 0.33899327 | H44: (Tiền gửi không kỳ hạn + Tiền ký quỹ) / (Tiền gửi của khách hàng)
B45: Chỉ số đòn bẩy | H45: Chỉ số đòn bẩy
...
