Workbook

Sheet Cân đối kế toán 
A1: BÁO CÁO TÀI CHÍNH NGÂN HÀNG
A2: Ngân hàng TMCP Ngoại thương Việt Nam
A5: KHU VỰC CHỌN NGÂN HÀNG | B5: Chọn mã CK | C5: Năm cuối cùng | D5: Đơn vị
B6: VCB | C6: 2023 | D6: Tỷ đồng
A8: BẢNG CÂN ĐỐI KẾ TOÁN | B8: 2019 | C8: 2020 | D8: 2021 | E8: 2022 | F8: 2023
A9: A. TỔNG TÀI SẢN (đồng) (Y) | B9: 1222718.9 | C9: 1326230.1 | D9: 1414672.6 | E9: 1813815.2 | F9: 1839613.2
A10: I. Tiền mặt, vàng bạc, đá quý (đồng) (Y) | B10: 13778.358 | C10: 15095.394 | D10: 18011.766 | E10: 18348.534 | F10: 14504.849
A11: II. Tiền gửi tại Ngân hàng nhà nước (đồng) (Y) | B11: 34684.091 | C11: 33139.373 | D11: 22506.711 | E11: 92557.809 | F11: 58104.503
A12: III. Tiền gửi và cho vay các TCTD khác (đồng) (Y) | B12: 249470.37 | C12: 267969.65 | D12: 225764.55 | E12: 313637.44 | F12: 336468.61
A13: 1. Tiền gửi tại các TCTD khác (đồng) (Y) | B13: 190100.33 | C13: 204713.78 | D13: 181036.98 | E13: 283727.72 | F13: 312001.88
A14: 2. Cho vay các TCTD khác (đồng) (Y) | B14: 62370.043 | C14: 64255.862 | D14: 48727.565 | E14: 40749.725 | F14: 30175.707
A15: 3. Dự phòng rủi ro cho vay TCTD khác (đồng) (Y) | B15: -3000 | C15: -1000 | D15: -4000 | E15: -10840 | F15: -5708.975
A16: IV. Chứng khoán kinh doanh ròng (đồng) (Y) | B16: 1801.126 | C16: 1954.061 | D16: 2766.098 | E16: 1499.687 | F16: 2495.408
A17: 1. Chứng khoán kinh doanh (đồng) (Y) | B17: 1889.628 | C17: 1991.861 | D17: 2822.531 | E17: 1543.575 | F17: 2511.395
A18: 2. Dự phòng rủi ro chứng khoán kinh doanh (đồng) (Y) | B18: -88.502 | C18: -37.8 | D18: -56.433 | E18: -43.888 | F18: -15.987
A19: V. Các CCTC phái sinh và TSTC khác (đồng) (Y) | B19: 98.312 | C19: 0 | D19: 303.202 | E19: 156.515 | F19: 0
... A78: VI. Lợi ích của cổ đông thiểu số (đồng) (Y) | B78: 83.459 | C78: 85.024 | D78: 87.113 | E78: 88.383 | F78: 93.99

Sheet Kết quả kinh doanh 
A1: BÁO CÁO TÀI CHÍNH NGÂN HÀNG
A2: ='Cân đối kế toán '!A2 -> Ngân hàng TMCP Ngoại thương Việt Nam
A4: BẢNG KẾT QUẢ HOẠT ĐỘNG KINH DOANH | B4: 2019 | C4: 2020 | D4: 2021 | E4: 2022 | F4: 2023
A5: 1. Thu nhập lãi và các khoản thu nhập tương tự (đồng) (Y) | B5: 67724.19 | C5: 69205.134 | D5: 70749.002 | E5: 88112.7 | F5: 108122.28
A6: 2. Chi phí lãi và các chi phí tương tự (đồng) (Y) | B6: -33146.84 | C6: -32919.659 | D6: -28349.385 | E6: -34866.222 | F6: -54501.409
A7: I. Thu nhập lãi thuần (đồng) (Y) | B7: 34577.35 | C7: 36285.475 | D7: 42399.617 | E7: 53246.478 | F7: 53620.869
A8: 3. Thu nhập từ hoạt động dịch vụ (đồng) (Y) | B8: 9002.507 | C8: 10588.163 | D8: 11286.516 | E8: 12425.007 | F8: 12632.739
A9: 4. Chi phí hoạt động dịch vụ (đồng) (Y) | B9: -4695.663 | C9: -3980.846 | D9: -3879.443 | E9: -5585.907 | F9: -6853.016
A10: II. Lãi thuần từ hoạt động dịch vụ (đồng) (Y) | B10: 4306.844 | C10: 6607.317 | D10: 7407.073 | E10: 6839.1 | F10: 5779.723
A11: III. Lãi/(lỗ) thuần từ ngoại hối và vàng (đồng) (Y) | B11: 3378.274 | C11: 3906.399 | D11: 4374.82 | E11: 5768.445 | F11: 5660.028
A12: IV. Lãi/(lỗ) thuần từ mua bán CKKD (đồng) (Y) | B12: 145.982 | C12: 1.81 | D12: 104.114 | E12: -115.194 | F12: 124.217
A13: V. Lãi/(lỗ) thuần từ mua bán CKĐT (đồng) (Y) | B13: 7.04 | C13: -0.098 | D13: -85.126 | E13: 81.595 | F13: 0
A14: 5. Thu nhập từ hoạt động khác (đồng) (Y) | B14: 3427.765 | C14: 2544.714 | D14: 3100.37 | E14: 2928.339 | F14: 4050.144
A15: 6. Chi phí hoạt động khác (đồng) (Y) | B15: -357.97 | C15: -744.461 | D15: -707.109 | E15: -874.378 | F15: -1777.975
... A28: XVI. Lợi nhuận sau thuế Ngân hàng mẹ (đồng) (Y) | B28: 18510.898 | C28: 18451.311 | D28: 21918.813 | E28: 29899.014 | F28: 33033.203

Sheet Thuyết minh
A1: BÁO CÁO TÀI CHÍNH NGÂN HÀNG
A2: ='Cân đối kế toán '!A2 -> Ngân hàng TMCP Ngoại thương Việt Nam
A4: BẢNG THUYẾT MINH | B4: 2019 | C4: 2020 | D4: 2021 | E4: 2022 | F4: 2023
A5: I. Chứng khoán kinh doanh (đồng) (Y) | B5: 1801.126 | C5: 1954.061 | D5: 2766.098 | E5: 1499.687 | F5: 2495.408
A6: 1. Chứng khoán nợ (đồng) (Y) | B6: 1538.592 | C6: 1665.791 | D6: 2492.178 | E6: 1397.467 | F6: 2249.222
A7: Chứng khoán Chính phủ (đồng) (Y) | B7: 994.592 | C7: 1126.417 | D7: 1493.814 | E7: 357.773 | F7: 669.306
A8: Chứng khoán do các TCTD khác trong nước phát hành (đồng) (Y) | B8: 0 | C8: 200.124 | D8: 499.364 | E8: 693.769 | F8: 1393.698
A9: Chứng khoán do các TCKT trong nước phát hành (đồng) (Y) | B9: 544 | C9: 339.25 | D9: 499 | E9: 345.925 | F9: 186.218
A10: Chứng khoán nợ khác (đồng) (Y) | B10: 0 | C10: 0 | D10: 0 | E10: 0 | F10: 0
A11: 2. Chứng khoán vốn (đồng) (Y) | B11: 351.036 | C11: 326.07 | D11: 330.353 | E11: 146.108 | F11: 262.173
A12: Chứng khoán vốn do các TCTD khác trong nước phát hành (đồng) (Y) | B12: 4.705 | C12: 29.437 | D12: 77.084 | E12: 12.531 | F12: 13.454
A13: Chứng khoán vốn do các TCKT khác trong nước phát hành (đồng) (Y) | B13: 346.331 | C13: 296.633 | D13: 253.269 | E13: 133.577 | F13: 248.719
A14: Chứng khoán vốn nước ngoài (đồng) (Y) | B14: 0 | C14: 0 | D14: 0 | E14: 0 | F14: 0
A15: Chứng khoán vốn khác (đồng) (Y) | B15: 0 | C15: 0 | D15: 0 | E15: 0 | F15: 0
... A105: Dự phòng trái phiếu đặc biệt (đồng) (Y) | B105: 0 | C105: 0 | D105: 0 | E105: 0 | F105: 0
A106: IX.b. Các khoản nợ chính phủ (Y) | B106: #VALUE! | C106: 41176.995 | D106: 9468.116 | E106: 67314.816 | F106: 1670.837
A107: 1. Vay ngân hàng Nhà nước (Y) | B107: #VALUE! | C107: 2347.294 | D107: 1749.584 | E107: 1253.828 | F107: 900.956
A108: Vay theo hồ sơ tín dụng (Y) | B108: #VALUE! | C108: 1800.563 | D108: 1415.715 | E108: 1055.777 | F108: 790.84
A109: Vay khác (Y) | B109: #VALUE! | C109: 546.731 | D109: 333.869 | E109: 198.051 | F109: 110.116
A110: 2. Tiền gửi của Kho bạc Nhà nước (Y) | B110: #VALUE! | C110: 36393.923 | D110: 7694.274 | E110: 49548.1 | F110: 769.881
A111: Tiền gửi không kì hạn (Y) | B111: #VALUE! | C111: 976.923 | D111: 694.274 | E111: 827.1 | F111: 769.881
A112: Tiền gửi có kì hạn (Y) | B112: #VALUE! | C112: 35417 | D112: 7000 | E112: 48721 | F112: 0
A113: 3. Tiền gửi của Ngân hàng Nhà nước Việt Nam (Y) | B113: #VALUE! | C113: 2435.778 | D113: 24.258 | E113: 16512.888 | F113: 0
A114: X. Tiền gửi theo loại hình (đồng) (Y) | B114: 928450.87 | C114: 1032113.6 | D114: 1135323.9 | E114: 1243468.5 | F114: 1395697.6
A115: 1. Tiền gửi không kỳ hạn (đồng) (Y) | B115: 262977.12 | C115: 307026.18 | D115: 367149.08 | E115: 402103.8 | F115: 461311.98
A116: 2. Tiền gửi tiết kiệm và có kỳ hạn (đồng) (Y) | B116: 642710.68 | C116: 693604.64 | D116: 730223.47 | E116: 821676.27 | F116: 904764.08
A117: 3. Tiền gửi vốn chuyên dùng (đồng) (Y) | B117: 21019.106 | C117: 27325.921 | D117: 31642.014 | E117: 9839.982 | F117: 17801.433
A118: 4. Tiền gửi ký quỹ (đồng) (Y) | B118: 1743.958 | C118: 4156.82 | D118: 6309.346 | E118: 9848.42 | F118: 11820.124
A119: 5. Tiền đảm bảo thanh toán khác (đồng) (Y) | B119: 0 | C119: 0 | D119: 0 | E119: 0 | F119: 0
A120: XI. Tiền gửi theo đối tượng (đồng) (Y) | B120: 928450.87 | C120: 1032113.6 | D120: 1135323.9 | E120: 1243468.5 | F120: 1395694.6
A121: 1. Các tổ chức kinh tế (đồng) (Y) | B121: 461608.93 | C121: 522325.06 | D121: 569423.28 | E121: 637317.09 | F121: 700983.32
A122: 2. Cá nhân (đồng) (Y) | B122: 466841.94 | C122: 509788.51 | D122: 565900.64 | E122: 606151.38 | F122: 694711.3
A123: XII. Phát hành giấy tờ có giá theo loại hình (đồng) (Y) | B123: 21383.932 | C123: 21240.197 | D123: 17387.747 | E123: 25337.894 | F123: 19912.623
A124: 1. Chứng chỉ tiền gửi (đồng) (Y) | B124: 1.016 | C124: 0.115 | D124: 0.115 | E124: 11000.115 | F124: 8000.115
A125: 2. Kỳ phiếu, Trái phiếu (đồng) (Y) | B125: 21382.916 | C125: 21240.082 | D125: 17387.632 | E125: 14337.779 | F125: 11912.508
... A207: 7. Chi phí khác (đồng) (Y) | B207: -43.512 | C207: -51.03 | D207: -71.85 | E207: -100.192 | F207: -100.31
A208: XXX. Tổng các chỉ tiêu ngoại bảng (Y) | B208: #VALUE! | C208: 214864.4 | D208: 200643.58 | E208: 801634.73 | F208: 929027.79
A209: 1. Bảo lãnh vay vốn (Y) | B209: #VALUE! | C209: 654.296 | D209: 2447.477 | E209: 2151.637 | F209: 306.384
A210: 2. Cam kết giao dịch hối đoái (Y) | B210: #VALUE! | C210: 116656.91 | D210: 81044.022 | E210: 83320.732 | F210: 111435.96
A211: Cam kết mua ngoại tệ (Y) | B211: #VALUE! | C211: 53984.032 | D211: 3470.214 | E211: 1027.038 | F211: 3375.603
...

Sheet Số liệu-Phân tích
B1: PHÂN TÍCH CÁC CHỈ SỐ TÀI CHÍNH
C3: 2020 | D3: 2021 | E3: 2022 | F3: 2023
B4: Tăng trưởng lợi nhuận | C4: ='Kết quả kinh doanh '!C26/'Kết quả kinh doanh '!B26-1 -> -0.0028862158 | D4: ='Kết quả kinh doanh '!D26/'Kết quả kinh doanh '!C26-1 -> 0.18765861 | E4: ='Kết quả kinh doanh '!E26/'Kết quả kinh doanh '!D26-1 -> 0.36373548 | F4: ='Kết quả kinh doanh '!F26/'Kết quả kinh doanh '!E26-1 -> 0.10479589
B5: Tăng trưởng tín dụng | C5: ='Cân đối kế toán '!C20/'Cân đối kế toán '!B20-1 -> 0.13289615 | D5: ='Cân đối kế toán '!D20/'Cân đối kế toán '!C20-1 -> 0.13921084 | E5: ='Cân đối kế toán '!E20/'Cân đối kế toán '!D20-1 -> 0.19845705 | F5: ='Cân đối kế toán '!F20/'Cân đối kế toán '!E20-1 -> 0.10835484
B6: Đòn bẩy tài chính A/E | C6: ='Cân đối kế toán '!C9/'Cân đối kế toán '!C66 -> 14.094589 | D6: ='Cân đối kế toán '!D9/'Cân đối kế toán '!D66 -> 12.964685 | E6: ='Cân đối kế toán '!E9/'Cân đối kế toán '!E66 -> 13.371674 | F6: ='Cân đối kế toán '!F9/'Cân đối kế toán '!F66 -> 11.148315
B7: Tỷ lệ nợ xấu (NPL) | C7: =SUM('Thuyết minh'!C32:C34)/'Thuyết minh'!C29 -> 0.0062272471 | D7: =SUM('Thuyết minh'!D32:D34)/'Thuyết minh'!D29 -> 0.0063711978 | E7: =SUM('Thuyết minh'!E32:E34)/'Thuyết minh'!E29 -> 0.0068296668 | F7: =SUM('Thuyết minh'!F32:F34)/'Thuyết minh'!F29 -> 0.009804289
B8: Tỷ lệ nợ quá hạn | C8: =('Thuyết minh'!C29-'Thuyết minh'!C30)/'Thuyết minh'!C29 -> 0.011412096 | D8: =('Thuyết minh'!D29-'Thuyết minh'!D30)/'Thuyết minh'!D29 -> 0.01001193 | E8: =('Thuyết minh'!E29-'Thuyết minh'!E30)/'Thuyết minh'!E29 -> 0.010395713 | F8: =('Thuyết minh'!F29-'Thuyết minh'!F30)/'Thuyết minh'!F29 -> 0.014180768
B9: Tỷ lệ bao phủ nợ xấu (LLR) | C9: =-'Cân đối kế toán '!C22/SUM('Thuyết minh'!C32:C34) -> 3.6796138 | D9: =-'Cân đối kế toán '!D22/SUM('Thuyết minh'!D32:D34) -> 4.243608 | E9: =-'Cân đối kế toán '!E22/SUM('Thuyết minh'!E32:E34) -> 3.1685529 | F9: =-'Cân đối kế toán '!F22/SUM('Thuyết minh'!F32:F34) -> 2.3029916
B10: Dự phòng rủi ro tín dụng/Cho vay | C10: =-'Cân đối kế toán '!C22/'Cân đối kế toán '!C21 -> 0.022913864 | D10: =-'Cân đối kế toán '!D22/'Cân đối kế toán '!D21 -> 0.027036866 | E10: =-'Cân đối kế toán '!E22/'Cân đối kế toán '!E21 -> 0.021640161 | F10: =-'Cân đối kế toán '!F22/'Cân đối kế toán '!F21 -> 0.022579196
B11: Chi phí hoạt động/Thu nhập hoạt động (CIR) | C11: =-'Kết quả kinh doanh '!C19/'Kết quả kinh doanh '!C18 -> 0.32689399 | D11: =-'Kết quả kinh doanh '!D19/'Kết quả kinh doanh '!D18 -> 0.30982162 | E11: =-'Kết quả kinh doanh '!E19/'Kết quả kinh doanh '!E18 -> 0.31212737 | F11: =-'Kết quả kinh doanh '!F19/'Kết quả kinh doanh '!F18 -> 0.3235939
B12: Chi phí lãi/Tiền gửi khách hàng | C12: =-'Thuyết minh'!C140/'Cân đối kế toán '!C56 -> 0.031895384 | D12: =-'Thuyết minh'!D140/'Cân đối kế toán '!D56 -> 0.024970306 | E12: =-'Thuyết minh'!E140/'Cân đối kế toán '!E56 -> 0.02803949 | F12: =-'Thuyết minh'!F140/'Cân đối kế toán '!F56 -> 0.039049582
B13: Chi phí hoạt động/Tổng tài sản | C13: =-'Kết quả kinh doanh '!C19/'Cân đối kế toán '!C9 -> 0.012093113 | D13: =-'Kết quả kinh doanh '!D19/'Cân đối kế toán '!D9 -> 0.012422795 | E13: =-'Kết quả kinh doanh '!E19/'Cân đối kế toán '!E9 -> 0.011715919 | F13: =-'Kết quả kinh doanh '!F19/'Cân đối kế toán '!F9 -> 0.011912775
B14: Chi phí vốn (COF) | C14: =-'Thuyết minh'!C140/((('Cân đối kế toán '!C52+'Cân đối kế toán '!C53+'Cân đối kế toán '!C56+'Cân đối kế toán '!C59)+('Cân đối kế toán '!B52+'Cân đối kế toán '!B53+'Cân đối kế toán '!B56+'Cân đối kế toán '!B59))/2) -> 0.028453433 | D14: =-'Thuyết minh'!D140/((('Cân đối kế toán '!D52+'Cân đối kế toán '!D53+'Cân đối kế toán '!D56+'Cân đối kế toán '!D59)+('Cân đối kế toán '!C52+'Cân đối kế toán '!C53+'Cân đối kế toán '!C56+'Cân đối kế toán '!C59))/2) -> 0.022954483 | E14: =-'Thuyết minh'!E140/((('Cân đối kế toán '!E52+'Cân đối kế toán '!E53+'Cân đối kế toán '!E56+'Cân đối kế toán '!E59)+('Cân đối kế toán '!D52+'Cân đối kế toán '!D53+'Cân đối kế toán '!D56+'Cân đối kế toán '!D59))/2) -> 0.024548754 | F14: =-'Thuyết minh'!F140/((('Cân đối kế toán '!F52+'Cân đối kế toán '!F53+'Cân đối kế toán '!F56+'Cân đối kế toán '!F59)+('Cân đối kế toán '!E52+'Cân đối kế toán '!E53+'Cân đối kế toán '!E56+'Cân đối kế toán '!E59))/2) -> 0.03406602
B15: Mức sinh lời trên tài sản (YEA) | C15: ='Kết quả kinh doanh '!C5/((('Cân đối kế toán '!C11+'Cân đối kế toán '!C12+'Cân đối kế toán '!C17+'Cân đối kế toán '!C21+'Cân đối kế toán '!C23)+('Cân đối kế toán '!B11+'Cân đối kế toán '!B12+'Cân đối kế toán '!B17+'Cân đối kế toán '!B21+'Cân đối kế toán '!B23))/2) -> 0.05562888 | D15: ='Kết quả kinh doanh '!D5/((('Cân đối kế toán '!D11+'Cân đối kế toán '!D12+'Cân đối kế toán '!D17+'Cân đối kế toán '!D21+'Cân đối kế toán '!D23)+('Cân đối kế toán '!C11+'Cân đối kế toán '!C12+'Cân đối kế toán '!C17+'Cân đối kế toán '!C21+'Cân đối kế toán '!C23))/2) -> 0.052753106 | E15: ='Kết quả kinh doanh '!E5/((('Cân đối kế toán '!E11+'Cân đối kế toán '!E12+'Cân đối kế toán '!E17+'Cân đối kế toán '!E21+'Cân đối kế toán '!E23)+('Cân đối kế toán '!D11+'Cân đối kế toán '!D12+'Cân đối kế toán '!D17+'Cân đối kế toán '!D21+'Cân đối kế toán '!D23))/2) -> 0.056276428 | F15: ='Kết quả kinh doanh '!F5/((('Cân đối kế toán '!F11+'Cân đối kế toán '!F12+'Cân đối kế toán '!F17+'Cân đối kế toán '!F21+'Cân đối kế toán '!F23)+('Cân đối kế toán '!E11+'Cân đối kế toán '!E12+'Cân đối kế toán '!E17+'Cân đối kế toán '!E21+'Cân đối kế toán '!E23))/2) -> 0.06070534
B16: Chênh lêch lãi suất đầu vào đầu ra (NIM) | C16: ='Kết quả kinh doanh '!C7/('Cân đối kế toán '!C11+'Cân đối kế toán '!C12+'Cân đối kế toán '!C17+'Cân đối kế toán '!C21+'Cân đối kế toán '!C23) -> 0.027915764 | D16: ='Kết quả kinh doanh '!D7/('Cân đối kế toán '!D11+'Cân đối kế toán '!D12+'Cân đối kế toán '!D17+'Cân đối kế toán '!D21+'Cân đối kế toán '!D23) -> 0.030669944 | E16: ='Kết quả kinh doanh '!E7/('Cân đối kế toán '!E11+'Cân đối kế toán '!E12+'Cân đối kế toán '!E17+'Cân đối kế toán '!E21+'Cân đối kế toán '!E23) -> 0.030444368 | F16: ='Kết quả kinh doanh '!F7/('Cân đối kế toán '!F11+'Cân đối kế toán '!F12+'Cân đối kế toán '!F17+'Cân đối kế toán '!F21+'Cân đối kế toán '!F23) -> 0.029572122
B17: Tỷ lệ thu nhập thuần từ hoạt động | C17: ='Kết quả kinh doanh '!C8/'Kết quả kinh doanh '!C18 -> 0.21580951 | D17: ='Kết quả kinh doanh '!D8/'Kết quả kinh doanh '!D18 -> 0.19897401 | E17: ='Kết quả kinh doanh '!E8/'Kết quả kinh doanh '!E18 -> 0.18249842 | F17: ='Kết quả kinh doanh '!F8/'Kết quả kinh doanh '!F18 -> 0.18653416
B18: LNST/TTS (ROA) | C18: ='Kết quả kinh doanh '!C26/AVERAGE('Cân đối kế toán '!B9:C9) -> 0.014494224 | D18: ='Kết quả kinh doanh '!D26/AVERAGE('Cân đối kế toán '!C9:D9) -> 0.016008627 | E18: ='Kết quả kinh doanh '!E26/AVERAGE('Cân đối kế toán '!D9:E9) -> 0.018534408 | F18: ='Kết quả kinh doanh '!F26/AVERAGE('Cân đối kế toán '!E9:F9) -> 0.01809503
B19: LNST/VCSH (ROE) | C19: ='Kết quả kinh doanh '!C26/AVERAGE('Cân đối kế toán '!B66:C66) -> 0.21114108 | D19: ='Kết quả kinh doanh '!D26/AVERAGE('Cân đối kế toán '!C66:D66) -> 0.21592234 | E19: ='Kết quả kinh doanh '!E26/AVERAGE('Cân đối kế toán '!D66:E66) -> 0.24447319 | F19: ='Kết quả kinh doanh '!F26/AVERAGE('Cân đối kế toán '!E66:F66) -> 0.21988017
B20: Tiền gửi không kỳ hạn/Tổng tiền gửi (CASA) | C20: ='Thuyết minh'!C115/'Thuyết minh'!C114 -> 0.29747325 | D20: ='Thuyết minh'!D115/'Thuyết minh'!D114 -> 0.32338708 | E20: ='Thuyết minh'!E115/'Thuyết minh'!E114 -> 0.32337274 | F20: ='Thuyết minh'!F115/'Thuyết minh'!F114 -> 0.3305243
B21: Dư nợ cấp tín dụng/Vốn huy động (LDR) | C21: ='Cân đối kế toán '!C21/('Cân đối kế toán '!C56+'Cân đối kế toán '!C59) -> 0.79725187 | D21: ='Cân đối kế toán '!D21/('Cân đối kế toán '!D56+'Cân đối kế toán '!D59) -> 0.83346945 | E21: ='Cân đối kế toán '!E21/('Cân đối kế toán '!E56+'Cân đối kế toán '!E59) -> 0.90247518 | F21: ='Cân đối kế toán '!F21/('Cân đối kế toán '!F56+'Cân đối kế toán '!F59) -> 0.89739321
B22: Tài sản thanh khoản cao/Tổng tài sản | C22: =SUM('Cân đối kế toán '!C10:C12)/'Cân đối kế toán '!C9 -> 0.23842349 | D22: =SUM('Cân đối kế toán '!D10:D12)/'Cân đối kế toán '!D9 -> 0.18822944 | E22: =SUM('Cân đối kế toán '!E10:E12)/'Cân đối kế toán '!E9 -> 0.23406122 | F22: =SUM('Cân đối kế toán '!F10:F12)/'Cân đối kế toán '!F9 -> 0.22237172

Sheet Biểu đồ-Phân tích
B1: PHÂN TÍCH CÁC CHỈ SỐ TÀI CHÍNH
B3: PHẦN 1: PHÂN TÍCH TĂNG TRƯỞNG
B6: Tăng trưởng lợi nhuận | M6: Tăng trưởng tín dụng
B21: PHẦN 2: PHÂN TÍCH AN TOÀN VỐN
B24: Đòn bẩy tài chính A/E
B39: PHẦN 3: PHÂN TÍCH CHẤT LƯỢNG TÀI SẢN
B42: Tỷ lệ nợ xấu (NPL) | M42: Tỷ lệ nợ quá hạn
B57: Tỷ lệ bao phủ nợ xấu (LLR) | M57: Dự phòng rủi ro tín dụng/Cho vay
B72: PHẦN 4: PHÂN TÍCH HIỆU QUẢ QUẢN TRỊ
B75: Chi phí hoạt động/Thu nhập hoạt động (CIR) | I75: Chi phí lãi/Tiền gửi khách hàng | P75: Chi phí hoạt động/Tổng tài sản
B90: PHẦN 5: PHÂN TÍCH MỨC SINH LỜI
B93: Chi phí vốn (COF) | M93: Mức sinh lời trên tài sản (YEA)
B108: Chênh lêch lãi suất đầu vào đầu ra (NIM) | M108: Tỷ lệ thu nhập thuần từ hoạt động
B123: LNST/TTS (ROA) | M123: LNST/VCSH (ROE)
B138: PHẦN 6: PHÂN TÍCH THANH KHOẢN
B141: Tiền gửi không kỳ hạn/Tổng tiền gửi (CASA) | I141: Dư nợ cấp tín dụng/Vốn huy động (LDR) | P141: Tài sản thanh khoản cao/Tổng tài sản

Sheet CĐKT-F
B1: DỰ PHÓNG BẢNG CĐKT
C4: Dữ liệu quá khứ | G4: Dữ liệu dự phóng | L4: CAGR
C5: 2020 | D5: =+C5+1 -> 2021 | E5: =+D5+1 -> 2022 | F5: =+E5+1 -> 2023 | G5: =+F5+1 -> 2024 | H5: =+G5+1 -> 2025 | I5: =+H5+1 -> 2026 | J5: =+I5+1 -> 2027 | K5: =+J5+1 -> 2028 | L5: =MID(F5,3,2)&"-"&MID(K5,3,2)&"F" -> 23-28F
B6: TỔNG TÀI SẢN | C6: =SUM(C7:C10) -> 1326230.1 | D6: =SUM(D7:D10) -> 1414672.6 | E6: =SUM(E7:E10) -> 1813815.2 | F6: =SUM(F7:F10) -> 1839613.2 | G6: =SUM(G7:G10) -> 1993677.6 | H6: =SUM(H7:H10) -> 2161653.6 | I6: =SUM(I7:I10) -> 2344857.7 | J6: =SUM(J7:J10) -> 2544734.1 | K6: =SUM(K7:K10) -> 2762867.6 | L6: =((K6/F6)^(1/5))-1 -> 0.084742639
B7: Cho vay khách hàng | C7: ='Cân đối kế toán '!C20 -> 820545.47 | D7: ='Cân đối kế toán '!D20 -> 934774.29 | E7: ='Cân đối kế toán '!E20 -> 1120286.8 | F7: ='Cân đối kế toán '!F20 -> 1241675.3 | G7: =F7*(1+G20) -> 1365842.9 | H7: =G7*(1+H20) -> 1502427.2 | I7: =H7*(1+I20) -> 1652669.9 | J7: =I7*(1+J20) -> 1817936.9 | K7: =J7*(1+K20) -> 1999730.5 | L7: =((K7/F7)^(1/5))-1 -> 0.1
B8: Cho vay các TCTD khác | C8: ='Cân đối kế toán '!C12 -> 267969.65 | D8: ='Cân đối kế toán '!D12 -> 225764.55 | E8: ='Cân đối kế toán '!E12 -> 313637.44 | F8: ='Cân đối kế toán '!F12 -> 336468.61 | G8: =F8*(1+G21) -> 353292.04 | H8: =G8*(1+H21) -> 370956.64 | I8: =H8*(1+I21) -> 389504.47 | J8: =I8*(1+J21) -> 408979.69 | K8: =J8*(1+K21) -> 429428.68 | L8: =((K8/F8)^(1/5))-1 -> 0.05
B9: Đầu tư | C9: ='Cân đối kế toán '!C16+'Cân đối kế toán '!C23+'Cân đối kế toán '!C27+'Cân đối kế toán '!C32+'Cân đối kế toán '!C42 -> 169663.53 | D9: ='Cân đối kế toán '!D16+'Cân đối kế toán '!D23+'Cân đối kế toán '!D27+'Cân đối kế toán '!D32+'Cân đối kế toán '!D42 -> 184343.02 | E9: ='Cân đối kế toán '!E16+'Cân đối kế toán '!E23+'Cân đối kế toán '!E27+'Cân đối kế toán '!E32+'Cân đối kế toán '!E42 -> 207849.83 | F9: ='Cân đối kế toán '!F16+'Cân đối kế toán '!F23+'Cân đối kế toán '!F27+'Cân đối kế toán '!F32+'Cân đối kế toán '!F42 -> 158208.6 | G9: =F9*(1+G22) -> 166119.03 | H9: =G9*(1+H22) -> 174424.98 | I9: =H9*(1+I22) -> 183146.23 | J9: =I9*(1+J22) -> 192303.54 | K9: =J9*(1+K22) -> 201918.72 | L9: =((K9/F9)^(1/5))-1 -> 0.05
B10: Khác | C10: ='Cân đối kế toán '!C10+'Cân đối kế toán '!C11+'Cân đối kế toán '!C19+'Cân đối kế toán '!C45 -> 68051.454 | D10: ='Cân đối kế toán '!D10+'Cân đối kế toán '!D11+'Cân đối kế toán '!D19+'Cân đối kế toán '!D45 -> 69790.737 | E10: ='Cân đối kế toán '!E10+'Cân đối kế toán '!E11+'Cân đối kế toán '!E19+'Cân đối kế toán '!E45 -> 172041.06 | F10: ='Cân đối kế toán '!F10+'Cân đối kế toán '!F11+'Cân đối kế toán '!F19+'Cân đối kế toán '!F45 -> 103260.66 | G10: =F10*(1+G23) -> 108423.69 | H10: =G10*(1+H23) -> 113844.87 | I10: =H10*(1+I23) -> 119537.12 | J10: =I10*(1+J23) -> 125513.97 | K10: =J10*(1+K23) -> 131789.67 | L10: =((K10/F10)^(1/5))-1 -> 0.05
B11: NGUỒN VỐN | C11: =SUM(C12:C16) -> 1326230.1 | D11: =SUM(D12:D16) -> 1414672.6 | E11: =SUM(E12:E16) -> 1813815.2 | F11: =SUM(F12:F16) -> 1839613.2 | G11: =SUM(G12:G16) -> 1993677.6 | H11: =SUM(H12:H16) -> 2161653.6 | I11: =SUM(I12:I16) -> 2344857.7 | J11: =SUM(J12:J16) -> 2544734.1 | K11: =SUM(K12:K16) -> 2762867.6 | L11: =((K11/F11)^(1/5))-1 -> 0.084742639
B12: Tiền gửi và vay các TCTD khác | C12: ='Cân đối kế toán '!C53 -> 103583.83 | D12: ='Cân đối kế toán '!D53 -> 109757.78 | E12: ='Cân đối kế toán '!E53 -> 232510.85 | F12: ='Cân đối kế toán '!F53 -> 213838.98 | G12: =F12*(1+G24) -> 235222.88 | H12: =G12*(1+H24) -> 258745.17 | I12: =H12*(1+I24) -> 284619.68 | J12: =I12*(1+J24) -> 313081.65 | K12: =J12*(1+K24) -> 344389.82 | L12: =((K12/F12)^(1/5))-1 -> 0.1
B13: Tiền gửi của khách hàng | C13: ='Cân đối kế toán '!C56 -> 1032113.6 | D13: ='Cân đối kế toán '!D56 -> 1135323.9 | E13: ='Cân đối kế toán '!E56 -> 1243468.5 | F13: ='Cân đối kế toán '!F56 -> 1395697.6 | G13: =F13*(1+G25) -> 1507353.4 | H13: =G13*(1+H25) -> 1627941.7 | I13: =H13*(1+I25) -> 1758177 | J13: =I13*(1+J25) -> 1898831.2 | K13: =J13*(1+K25) -> 2050737.7 | L13: =((K13/F13)^(1/5))-1 -> 0.08
B14: Phát hành giấy tờ có giá | C14: ='Cân đối kế toán '!C59 -> 21240.197 | D14: ='Cân đối kế toán '!D59 -> 17387.747 | E14: ='Cân đối kế toán '!E59 -> 25337.894 | F14: ='Cân đối kế toán '!F59 -> 19912.623 | G14: =F14*(1+G26) -> 24890.779 | H14: =G14*(1+H26) -> 31113.473 | I14: =H14*(1+I26) -> 38891.842 | J14: =I14*(1+J26) -> 48614.802 | K14: =J14*(1+K26) -> 60768.503 | L14: =((K14/F14)^(1/5))-1 -> 0.25
B15: Vốn chủ sở hữu | C15: ='Cân đối kế toán '!C66 -> 94094.979 | D15: ='Cân đối kế toán '!D66 -> 109117.39 | E15: ='Cân đối kế toán '!E66 -> 135646.08 | F15: ='Cân đối kế toán '!F66 -> 165012.67 | G15: =F15+'KQKD-F'!G20 -> 201544.88 | H15: =G15+'KQKD-F'!H20 -> 241546.32 | I15: =H15+'KQKD-F'!I20 -> 285366.19 | J15: =I15+'KQKD-F'!J20 -> 333386.33 | K15: =J15+'KQKD-F'!K20 -> 386023.46 | L15: =((K15/F15)^(1/5))-1 -> 0.18527544
B16: Khác | C16: ='Cân đối kế toán '!C52+'Cân đối kế toán '!C57+'Cân đối kế toán '!C58+'Cân đối kế toán '!C60 -> 75197.516 | D16: ='Cân đối kế toán '!D52+'Cân đối kế toán '!D57+'Cân đối kế toán '!D58+'Cân đối kế toán '!D60 -> 43085.757 | E16: ='Cân đối kế toán '!E52+'Cân đối kế toán '!E57+'Cân đối kế toán '!E58+'Cân đối kế toán '!E60 -> 176851.87 | F16: ='Cân đối kế toán '!F52+'Cân đối kế toán '!F57+'Cân đối kế toán '!F58+'Cân đối kế toán '!F60 -> 45151.318 | G16: =G6-SUM(G12:G15) -> 24665.664 | H16: =H6-SUM(H12:H15) -> 2306.9988 | I16: =I6-SUM(I12:I15) -> -22197.058 | J16: =J6-SUM(J12:J15) -> -49179.911 | K16: =K6-SUM(K12:K15) -> -79051.853 | L16: =((K16/F16)^(1/5))-1 -> -2.1185318
B19: Giả định | C19: =C5 -> 2020 | D19: =D5 -> 2021 | E19: =E5 -> 2022 | F19: =F5 -> 2023 | G19: =G5 -> 2024 | H19: =H5 -> 2025 | I19: =I5 -> 2026 | J19: =J5 -> 2027 | K19: =K5 -> 2028
B20: Tăng trưởng CVKH | D20: =(D7/C7)-1 -> 0.13921084 | E20: =(E7/D7)-1 -> 0.19845705 | F20: =(F7/E7)-1 -> 0.10835484 | G20: 0.1 | H20: =G20 -> 0.1 | I20: =H20 -> 0.1 | J20: =I20 -> 0.1 | K20: =J20 -> 0.1
B21: Tăng trưởng CV các TCTD khác | D21: =(D8/C8)-1 -> -0.15749955 | E21: =(E8/D8)-1 -> 0.38922364 | F21: =(F8/E8)-1 -> 0.072794762 | G21: 0.05 | H21: =G21 -> 0.05 | I21: =H21 -> 0.05 | J21: =I21 -> 0.05 | K21: =J21 -> 0.05
B22: Tăng trưởng đầu tư | D22: =(D9/C9)-1 -> 0.086521195 | E22: =(E9/D9)-1 -> 0.12751673 | F22: =(F9/E9)-1 -> -0.2388322 | G22: 0.05 | H22: =G22 -> 0.05 | I22: =H22 -> 0.05 | J22: =I22 -> 0.05 | K22: =J22 -> 0.05
B23: Tăng trưởng khác | D23: =(D10/C10)-1 -> 0.025558352 | E23: =(E10/D10)-1 -> 1.4650988 | F23: =(F10/E10)-1 -> -0.39979062 | G23: 0.05 | H23: =G23 -> 0.05 | I23: =H23 -> 0.05 | J23: =I23 -> 0.05 | K23: =J23 -> 0.05
B24: Tăng trưởng tiền gửi và vay các TCTD khác | D24: =(D12/C12)-1 -> 0.059603355 | E24: =(E12/D12)-1 -> 1.1183998 | F24: =(F12/E12)-1 -> -0.080305371 | G24: 0.1 | H24: =G24 -> 0.1 | I24: =H24 -> 0.1 | J24: =I24 -> 0.1 | K24: =J24 -> 0.1
B25: Tăng trưởng tiền gửi của khách hàng | D25: =(D13/C13)-1 -> 0.099999021 | E25: =(E13/D13)-1 -> 0.095254365 | F25: =(F13/E13)-1 -> 0.122423 | G25: 0.08 | H25: =G25 -> 0.08 | I25: =H25 -> 0.08 | J25: =I25 -> 0.08 | K25: =J25 -> 0.08
B26: Tăng trưởng phát hành giấy tờ có giá | D26: =(D14/C14)-1 -> -0.18137544 | E26: =(E14/D14)-1 -> 0.45722698 | F26: =(F14/E14)-1 -> -0.21411689 | G26: 0.25 | H26: =G26 -> 0.25 | I26: =H26 -> 0.25 | J26: =I26 -> 0.25 | K26: =J26 -> 0.25
B27: Tăng trưởng khác | D27: =(D16/C16)-1 -> -0.42703218 | E27: =(E16/D16)-1 -> 3.1046481 | F27: =(F16/E16)-1 -> -0.74469414 | G27: 0.1 | H27: =G27 -> 0.1 | I27: =H27 -> 0.1 | J27: =I27 -> 0.1 | K27: =J27 -> 0.1

Sheet KQKD-F
B1: DỰ PHÓNG KQKD
C4: Dữ liệu quá khứ | G4: Dữ liệu dự phóng | L4: CAGR
C5: 2020 | D5: =+C5+1 -> 2021 | E5: =+D5+1 -> 2022 | F5: =+E5+1 -> 2023 | G5: =+F5+1 -> 2024 | H5: =+G5+1 -> 2025 | I5: =+H5+1 -> 2026 | J5: =+I5+1 -> 2027 | K5: =+J5+1 -> 2028 | L5: =MID(F5,3,2)&"-"&MID(K5,3,2)&"F" -> 23-28F
B6: Thu nhập lãi thuần | C6: =SUM(C7:C8) -> 36285.475 | D6: =SUM(D7:D8) -> 42399.617 | E6: =SUM(E7:E8) -> 53246.478 | F6: =SUM(F7:F8) -> 53620.869 | G6: =SUM(G7:G8) -> 61091.366 | H6: =SUM(H7:H8) -> 66398.138 | I6: =SUM(I7:I8) -> 72201.036 | J6: =SUM(J7:J8) -> 78545.193 | K6: =SUM(K7:K8) -> 85479.01 | L6: =((K6/F6)^(1/5))-1 -> 0.09775425
B7: Thu nhập lãi và các khoản thu nhập tương tự | C7: ='Kết quả kinh doanh '!C5 -> 69205.134 | D7: ='Kết quả kinh doanh '!D5 -> 70749.002 | E7: ='Kết quả kinh doanh '!E5 -> 88112.7 | F7: ='Kết quả kinh doanh '!F5 -> 108122.28 | G7: =(SUM('CĐKT-F'!G7:G9)+SUM('CĐKT-F'!F7:F9))/2*'KQKD-F'!G26 -> 108648.19 | H7: =(SUM('CĐKT-F'!H7:H9)+SUM('CĐKT-F'!G7:G9))/2*'KQKD-F'!H26 -> 117991.88 | I7: =(SUM('CĐKT-F'!I7:I9)+SUM('CĐKT-F'!H7:H9))/2*'KQKD-F'!I26 -> 128193.88 | J7: =(SUM('CĐKT-F'!J7:J9)+SUM('CĐKT-F'!I7:I9))/2*'KQKD-F'!J26 -> 139336.22 | K7: =(SUM('CĐKT-F'!K7:K9)+SUM('CĐKT-F'!J7:J9))/2*'KQKD-F'!K26 -> 151508.94 | L7: =((K7/F7)^(1/5))-1 -> 0.06980498
B8: Chi phí lãi và các chi phí tương tự | C8: ='Kết quả kinh doanh '!C6 -> -32919.659 | D8: ='Kết quả kinh doanh '!D6 -> -28349.385 | E8: ='Kết quả kinh doanh '!E6 -> -34866.222 | F8: ='Kết quả kinh doanh '!F6 -> -54501.409 | G8: =-(SUM('CĐKT-F'!G12:G14)+SUM('CĐKT-F'!F12:F14))/2*'KQKD-F'!G27 -> -47556.828 | H8: =-(SUM('CĐKT-F'!H12:H14)+SUM('CĐKT-F'!G12:G14))/2*'KQKD-F'!H27 -> -51593.744 | I8: =-(SUM('CĐKT-F'!I12:I14)+SUM('CĐKT-F'!H12:H14))/2*'KQKD-F'!I27 -> -55992.844 | J8: =-(SUM('CĐKT-F'!J12:J14)+SUM('CĐKT-F'!I12:I14))/2*'KQKD-F'!J27 -> -60791.027 | K8: =-(SUM('CĐKT-F'!K12:K14)+SUM('CĐKT-F'!J12:J14))/2*'KQKD-F'!K27 -> -66029.931 | L8: =((K8/F8)^(1/5))-1 -> 0.039122199
B9: Lãi thuần từ hoạt động dịch vụ | C9: ='Kết quả kinh doanh '!C10 -> 6607.317 | D9: ='Kết quả kinh doanh '!D10 -> 7407.073 | E9: ='Kết quả kinh doanh '!E10 -> 6839.1 | F9: ='Kết quả kinh doanh '!F10 -> 5779.723 | G9: =F9*(1+G28) -> 6068.7092 | H9: =G9*(1+H28) -> 6372.1446 | I9: =H9*(1+I28) -> 6690.7518 | J9: =I9*(1+J28) -> 7025.2894 | K9: =J9*(1+K28) -> 7376.5539 | L9: =((K9/F9)^(1/5))-1 -> 0.05
B10: Lãi/Lỗ từ hoạt động đầu tư | C10: =SUM('Kết quả kinh doanh '!C11:C13) -> 3908.111 | D10: =SUM('Kết quả kinh doanh '!D11:D13) -> 4393.808 | E10: =SUM('Kết quả kinh doanh '!E11:E13) -> 5734.846 | F10: =SUM('Kết quả kinh doanh '!F11:F13) -> 5784.245 | G10: =F10*(1+G29) -> 6246.9846 | H10: =G10*(1+H29) -> 6746.7434 | I10: =H10*(1+I29) -> 7286.4828 | J10: =I10*(1+J29) -> 7869.4015 | K10: =J10*(1+K29) -> 8498.9536 | L10: =((K10/F10)^(1/5))-1 -> 0.08
B11: Lãi/Lỗ từ hoạt động khác | C11: =SUM('Kết quả kinh doanh '!C16:C17) -> 2261.638 | D11: =SUM('Kết quả kinh doanh '!D16:D17) -> 2523.071 | E11: =SUM('Kết quả kinh doanh '!E16:E17) -> 2262.397 | F11: =SUM('Kết quả kinh doanh '!F16:F17) -> 2538.625 | G11: =F11 -> 2538.625 | H11: =G11 -> 2538.625 | I11: =H11 -> 2538.625 | J11: =I11 -> 2538.625 | K11: =J11 -> 2538.625 | L11: =((K11/F11)^(1/5))-1 -> 0
B12: Tổng thu nhập hoạt động | C12: =C11+C10+C9+C6 -> 49062.541 | D12: =D11+D10+D9+D6 -> 56723.569 | E12: =E11+E10+E9+E6 -> 68082.821 | F12: =F11+F10+F9+F6 -> 67723.462 | G12: =G11+G10+G9+G6 -> 75945.685 | H12: =H11+H10+H9+H6 -> 82055.651 | I12: =I11+I10+I9+I6 -> 88716.896 | J12: =J11+J10+J9+J6 -> 95978.509 | K12: =K11+K10+K9+K6 -> 103893.14 | L12: =((K12/F12)^(1/5))-1 -> 0.089355289
B13: Chi phí hoạt động | C13: ='Kết quả kinh doanh '!C19 -> -16038.25 | D13: ='Kết quả kinh doanh '!D19 -> -17574.188 | E13: ='Kết quả kinh doanh '!E19 -> -21250.512 | F13: ='Kết quả kinh doanh '!F19 -> -21914.899 | G13: =F13*(1+G30) -> -23010.644 | H13: =G13*(1+H30) -> -24161.176 | I13: =H13*(1+I30) -> -25369.235 | J13: =I13*(1+J30) -> -26637.697 | K13: =J13*(1+K30) -> -27969.582 | L13: =((K13/F13)^(1/5))-1 -> 0.05
B14: Lợi nhuận thuần HDKD trước DPRRTD | C14: =C12+C13 -> 33024.291 | D14: =D12+D13 -> 39149.381 | E14: =E12+E13 -> 46832.309 | F14: =F12+F13 -> 45808.563 | G14: =SUM(G12:G13) -> 52935.041 | H14: =H12+H13 -> 57894.474 | I14: =I12+I13 -> 63347.661 | J14: =J12+J13 -> 69340.812 | K14: =K12+K13 -> 75923.561 | L14: =((K14/F14)^(1/5))-1 -> 0.10633329
B15: Chi phí dự phòng rủi ro tín dụng | C15: ='Kết quả kinh doanh '!C21 -> -9974.73 | D15: ='Kết quả kinh doanh '!D21 -> -11760.801 | E15: ='Kết quả kinh doanh '!E21 -> -9464.218 | F15: ='Kết quả kinh doanh '!F21 -> -4564.876 | G15: =-(SUM('CĐKT-F'!G7:G9)+SUM('CĐKT-F'!F7:F9))/2*'KQKD-F'!G31 -> -7243.213 | H15: =-(SUM('CĐKT-F'!H7:H9)+SUM('CĐKT-F'!G7:G9))/2*'KQKD-F'!H31 -> -7866.1254 | I15: =-(SUM('CĐKT-F'!I7:I9)+SUM('CĐKT-F'!H7:H9))/2*'KQKD-F'!I31 -> -8546.2587 | J15: =-(SUM('CĐKT-F'!J7:J9)+SUM('CĐKT-F'!I7:I9))/2*'KQKD-F'!J31 -> -9289.0813 | K15: =-(SUM('CĐKT-F'!K7:K9)+SUM('CĐKT-F'!J7:J9))/2*'KQKD-F'!K31 -> -10100.596 | L15: =((K15/F15)^(1/5))-1 -> 0.17215111
B16: Tổng lợi nhuận trước thuế | C16: =C14+C15 -> 23049.561 | D16: =D14+D15 -> 27388.58 | E16: =E14+E15 -> 37368.091 | F16: =F14+F15 -> 41243.687 | G16: =G14+G15 -> 45691.828 | H16: =H14+H15 -> 50028.349 | I16: =I14+I15 -> 54801.402 | J16: =J14+J15 -> 60051.731 | K16: =K14+K15 -> 65822.965 | L16: =((K16/F16)^(1/5))-1 -> 0.098004175
B17: Chi phí thuế thu nhập doanh nghiệp | C17: ='Kết quả kinh doanh '!C25 -> -4577.043 | D17: ='Kết quả kinh doanh '!D25 -> -5449.535 | E17: ='Kết quả kinh doanh '!E25 -> -7449.037 | F17: ='Kết quả kinh doanh '!F25 -> -8189.239 | G17: =-G16*G32 -> -9138.3656 | H17: =-H16*H32 -> -10005.67 | I17: =-I16*I32 -> -10960.28 | J17: =-J16*J32 -> -12010.346 | K17: =-K16*K32 -> -13164.593 | L17: =((K17/F17)^(1/5))-1 -> 0.099595054
B18: Lợi nhuận sau thuế | C18: =C16+C17 -> 18472.518 | D18: =D16+D17 -> 21939.045 | E18: =E16+E17 -> 29919.054 | F18: =F16+F17 -> 33054.448 | G18: =G16+G17 -> 36553.462 | H18: =H16+H17 -> 40022.679 | I18: =I16+I17 -> 43841.122 | J18: =J16+J17 -> 48041.385 | K18: =K16+K17 -> 52658.372 | L18: =((K18/F18)^(1/5))-1 -> 0.097608606
B19: Lợi ích của cổ đông thiểu số | C19: ='Kết quả kinh doanh '!C27 -> 21.207 | D19: ='Kết quả kinh doanh '!D27 -> 20.232 | E19: ='Kết quả kinh doanh '!E27 -> 20.04 | F19: ='Kết quả kinh doanh '!F27 -> 21.245 | G19: =F19 -> 21.245 | H19: =G19 -> 21.245 | I19: =H19 -> 21.245 | J19: =I19 -> 21.245 | K19: =J19 -> 21.245 | L19: =((K19/F19)^(1/5))-1 -> 0
B20: Lợi nhuận sau thuế Ngân hàng mẹ | C20: =C18-C19 -> 18451.311 | D20: =D18-D19 -> 21918.813 | E20: =E18-E19 -> 29899.014 | F20: =F18-F19 -> 33033.203 | G20: =G18-G19 -> 36532.217 | H20: =H18-H19 -> 40001.434 | I20: =I18-I19 -> 43819.877 | J20: =J18-J19 -> 48020.14 | K20: =K18-K19 -> 52637.127 | L20: =((K20/F20)^(1/5))-1 -> 0.097661162
B25: Giả định | C25: =C5 -> 2020 | D25: =D5 -> 2021 | E25: =E5 -> 2022 | F25: =F5 -> 2023 | G25: =G5 -> 2024 | H25: =H5 -> 2025 | I25: =I5 -> 2026 | J25: =J5 -> 2027 | K25: =K5 -> 2028
B26: YEA | C26: ='Kết quả kinh doanh '!C5/((('Cân đối kế toán '!C11+'Cân đối kế toán '!C12+'Cân đối kế toán '!C17+'Cân đối kế toán '!C21+'Cân đối kế toán '!C23)+('Cân đối kế toán '!B11+'Cân đối kế toán '!B12+'Cân đối kế toán '!B17+'Cân đối kế toán '!B21+'Cân đối kế toán '!B23))/2) -> 0.05562888 | D26: ='Kết quả kinh doanh '!D5/((('Cân đối kế toán '!D11+'Cân đối kế toán '!D12+'Cân đối kế toán '!D17+'Cân đối kế toán '!D21+'Cân đối kế toán '!D23)+('Cân đối kế toán '!C11+'Cân đối kế toán '!C12+'Cân đối kế toán '!C17+'Cân đối kế toán '!C21+'Cân đối kế toán '!C23))/2) -> 0.052753106 | E26: ='Kết quả kinh doanh '!E5/((('Cân đối kế toán '!E11+'Cân đối kế toán '!E12+'Cân đối kế toán '!E17+'Cân đối kế toán '!E21+'Cân đối kế toán '!E23)+('Cân đối kế toán '!D11+'Cân đối kế toán '!D12+'Cân đối kế toán '!D17+'Cân đối kế toán '!D21+'Cân đối kế toán '!D23))/2) -> 0.056276428 | F26: ='Kết quả kinh doanh '!F5/((('Cân đối kế toán '!F11+'Cân đối kế toán '!F12+'Cân đối kế toán '!F17+'Cân đối kế toán '!F21+'Cân đối kế toán '!F23)+('Cân đối kế toán '!E11+'Cân đối kế toán '!E12+'Cân đối kế toán '!E17+'Cân đối kế toán '!E21+'Cân đối kế toán '!E23))/2) -> 0.06070534 | G26: 0.06 | H26: =G26 -> 0.06 | I26: =H26 -> 0.06 | J26: =I26 -> 0.06 | K26: =J26 -> 0.06
B27: COF | C27: =-'Thuyết minh'!C140/((('Cân đối kế toán '!C52+'Cân đối kế toán '!C53+'Cân đối kế toán '!C56+'Cân đối kế toán '!C59)+('Cân đối kế toán '!B52+'Cân đối kế toán '!B53+'Cân đối kế toán '!B56+'Cân đối kế toán '!B59))/2) -> 0.028453433 | D27: =-'Thuyết minh'!D140/((('Cân đối kế toán '!D52+'Cân đối kế toán '!D53+'Cân đối kế toán '!D56+'Cân đối kế toán '!D59)+('Cân đối kế toán '!C52+'Cân đối kế toán '!C53+'Cân đối kế toán '!C56+'Cân đối kế toán '!C59))/2) -> 0.022954483 | E27: =-'Thuyết minh'!E140/((('Cân đối kế toán '!E52+'Cân đối kế toán '!E53+'Cân đối kế toán '!E56+'Cân đối kế toán '!E59)+('Cân đối kế toán '!D52+'Cân đối kế toán '!D53+'Cân đối kế toán '!D56+'Cân đối kế toán '!D59))/2) -> 0.024548754 | F27: =-'Thuyết minh'!F140/((('Cân đối kế toán '!F52+'Cân đối kế toán '!F53+'Cân đối kế toán '!F56+'Cân đối kế toán '!F59)+('Cân đối kế toán '!E52+'Cân đối kế toán '!E53+'Cân đối kế toán '!E56+'Cân đối kế toán '!E59))/2) -> 0.03406602 | G27: 0.028 | H27: =G27 -> 0.028 | I27: =H27 -> 0.028 | J27: =I27 -> 0.028 | K27: =J27 -> 0.028
B28: Tăng trưởng thu nhập hoạt động dịch vụ | D28: =D9/C9-1 -> 0.12104096 | E28: =E9/D9-1 -> -0.076679817 | F28: =F9/E9-1 -> -0.15490006 | G28: 0.05 | H28: =G28 -> 0.05 | I28: =H28 -> 0.05 | J28: =I28 -> 0.05 | K28: =J28 -> 0.05
B29: Tăng trưởng thu nhập thuần từ đầu tư | D29: =IFERROR(IF(OR(D10<0,C10<0),0,(D10/C10)-1),0) -> 0.12427922 | E29: =IFERROR(IF(OR(E10<0,D10<0),0,(E10/D10)-1),0) -> 0.30521088 | F29: =IFERROR(IF(OR(F10<0,E10<0),0,(F10/E10)-1),0) -> 0.008613832 | G29: 0.08 | H29: =G29 -> 0.08 | I29: =H29 -> 0.08 | J29: =I29 -> 0.08 | K29: =J29 -> 0.08
B30: Tăng trưởng chi phí hoạt động | D30: =IFERROR(IF(OR(D11<0,C11<0),0,(D11/C11)-1),0) -> 0.11559454 | E30: =IFERROR(IF(OR(E11<0,D11<0),0,(E11/D11)-1),0) -> -0.10331616 | F30: =IFERROR(IF(OR(F11<0,E11<0),0,(F11/E11)-1),0) -> 0.12209528 | G30: 0.05 | H30: =G30 -> 0.05 | I30: =H30 -> 0.05 | J30: =I30 -> 0.05 | K30: =J30 -> 0.05
B31: Tỷ lệ chi phí dự phòng rủi ro tín dụng | D31: =-D15/('CĐKT-F'!D7+'CĐKT-F'!C7) -> 0.0067000904 | E31: =-E15/('CĐKT-F'!E7+'CĐKT-F'!D7) -> 0.0046053219 | F31: =-F15/('CĐKT-F'!F7+'CĐKT-F'!E7) -> 0.0019326626 | G31: 0.004 | H31: =G31 -> 0.004 | I31: =H31 -> 0.004 | J31: =I31 -> 0.004 | K31: =J31 -> 0.004
B32: Tỷ lệ chi phí thuế thu nhập doanh nghiệp | C32: =-C17/C16 -> 0.19857398 | D32: =-D17/D16 -> 0.19897107 | E32: =-E17/E16 -> 0.19934219 | F32: =-F17/F16 -> 0.19855739 | G32: 0.2 | H32: =G32 -> 0.2 | I32: =H32 -> 0.2 | J32: =I32 -> 0.2 | K32: =J32 -> 0.2

Sheet Định giá
B1: TỔNG HỢP ĐỊNH GIÁ CỔ PHIẾU
B3: ĐỊNH GIÁ P/B
B5: ĐỊnh giá P/B | C5: =C20 -> 2023 | D5: =D20 -> 2024
B6: Vốn chủ sở hữu (tỷ đồng) | C6: ='CĐKT-F'!F15 -> 165012.67 | D6: ='CĐKT-F'!G15 -> 201544.88
B7: Số lượng cổ phiếu đang lưu hành (triệu cp) | C7: 5589.0913 | D7: =C7 -> 5589.0913
B8: Giá trị sổ sách (đồng/cp) | C8: =C6/C7*10^3 -> 29524.06 | D8: =D6/D7*10^3 -> 36060.403
B9: Giá đóng cửa hiện hành | C9: 92000
B10: P/B | C10: =C9/C8 -> 3.1161026 | D10: 3.8
B12: Định giá theo PB | D12: =(D10*D8) -> 137029.53
B14: ĐỊNH GIÁ THEO MÔ HÌNH RIM
B16: Giả định của Mô hình RIM
B17: Tốc độ tăng trưởng dài hạn | D17: 0.05
B18: Tỷ suất sinh lợi yêu cầu | D18: 0.12
B20: Chỉ tiêu của Mô hình RIM | C20: 2023 | D20: 2024 | E20: 2025 | F20: 2026 | G20: 2027 | H20: 2028
B21: Vốn chủ sở hữu (tỷ đồng) | C21: ='CĐKT-F'!F15 -> 165012.67 | D21: ='CĐKT-F'!G15 -> 201544.88 | E21: ='CĐKT-F'!H15 -> 241546.32 | F21: ='CĐKT-F'!I15 -> 285366.19 | G21: ='CĐKT-F'!J15 -> 333386.33 | H21: ='CĐKT-F'!K15 -> 386023.46
B22: Lợi nhuận sau thuế TNDN (tỷ đồng) | C22: ='KQKD-F'!F20 -> 33033.203 | D22: ='KQKD-F'!G20 -> 36532.217 | E22: ='KQKD-F'!H20 -> 40001.434 | F22: ='KQKD-F'!I20 -> 43819.877 | G22: ='KQKD-F'!J20 -> 48020.14 | H22: ='KQKD-F'!K20 -> 52637.127
B23: Số lượng cổ phiếu lưu hành (triệu cp) | C23: =C7 -> 5589.0913 | D23: =C23 -> 5589.0913 | E23: =D23 -> 5589.0913 | F23: =E23 -> 5589.0913 | G23: =F23 -> 5589.0913 | H23: =G23 -> 5589.0913
B24: EPS - Earnings Per Share (đồng/cp) | C24: =C22/C23*10^3 -> 5910.2994 | D24: =D22/D23*10^3 -> 6536.343 | E24: =E22/E23*10^3 -> 7157.0551 | F24: =F22/F23*10^3 -> 7840.2507 | G24: =G22/G23*10^3 -> 8591.7616 | H24: =H22/H23*10^3 -> 9417.8328
B25: Giá trị sổ sách (đồng/cp) | C25: =C21/C23*10^3 -> 29524.06 | D25: =D21/D23*10^3 -> 36060.403 | E25: =E21/E23*10^3 -> 43217.458 | F25: =F21/F23*10^3 -> 51057.709 | G25: =G21/G23*10^3 -> 59649.47 | H25: =H21/H23*10^3 -> 69067.303
B26: ROEA (%) | D26: =D22/AVERAGE(C21:D21) -> 0.19932596 | E26: =E22/AVERAGE(D21:E21) -> 0.18055621 | F26: =F22/AVERAGE(E21:F21) -> 0.16632695 | G26: =G22/AVERAGE(F21:G21) -> 0.15521598 | H26: =H22/AVERAGE(G21:H21) -> 0.1463342
B27: RE - Residual Income (đồng/cp) | D27: =(D26-$D$18)*C25 -> 2342.0244 | E27: =(E26-$D$18)*D25 -> 2183.6814 | F27: =(F26-$D$18)*E25 -> 2002.1332 | G27: =(G26-$D$18)*F25 -> 1798.0472 | H27: =(H26-$D$18)*G25 -> 1570.8208
B28: Tỷ lệ chiết khấu lũy kế (lần) | D28: 1 | E28: =(1+$D$18)^1 -> 1.12 | F28: =(1+$D$18)^2 -> 1.2544 | G28: =(1+$D$18)^3 -> 1.404928 | H28: =(1+$D$18)^4 -> 1.5735194
B29: PV của RE (đồng) | D29: =D27/D28 -> 2342.0244 | E29: =E27/E28 -> 1949.7155 | F29: =F27/F28 -> 1596.0883 | G29: =G27/G28 -> 1279.8145 | H29: =H27/H28 -> 998.28503
B30: Tổng PV của RE (đồng) | D30: =SUM(D29:H29) -> 8165.9277
B31: PV của giá trị sau giai đoạn dự báo (đồng) | D31: =((H27*(1+D17))/(D18-D17))/(1+D18)^5 -> 13369.889
B33: Định giá theo Mô hình RIM | D33: =(D25+D30+D31) -> 57596.22
B37: Phương pháp định giá | C37: Giá dự phóng | D37: Tỷ trọng | E37: Giá dự phóng theo tỷ trọng
B38: Lợi nhuận thặng dư (RIM) | C38: =D33 -> 57596.22 | D38: 0.5 | E38: =D38*C38 -> 28798.11
B39: P/B | C39: =D12 -> 137029.53 | D39: 0.5 | E39: =D39*C39 -> 68514.766
B40: Giá mục tiêu | E40: =SUM(E38:E39) -> 97312.876
